Workbook

Sheet Dashboard
B1: m | C1: Total | D1: المتبقي | H1: NO. | I1: اسم القناة المغذية | J1: متر طول المنفذ | K1: التصميمي | L1: المتبقي
A2: DC34 | B2: ='ملخص الفرز'!I2 -> 1743 | C2: 1735 | D2: =C2-B2 -> -8 | H2: 1 | I2: ='ملخص الفرز'!B2 -> D28-1L | J2: ='ملخص الفرز'!C2 -> 897 | K2: ='ملخص الفرز'!F2 -> 925 | L2: =K2-J2 -> 28
A3: DC35 | B3: ='ملخص الفرز'!I3 -> 564 | C3: 640 | D3: =C3-B3 -> 76 | H3: 2 | I3: ='ملخص الفرز'!B3 -> D28-2L | J3: ='ملخص الفرز'!C3 -> 1371 | K3: ='ملخص الفرز'!F3 -> 1400 | L3: =K3-J3 -> 29
A4: DC36 | B4: ='ملخص الفرز'!I4 -> 363 | C4: 360 | D4: =C4-B4 -> -3 | H4: 3 | I4: ='ملخص الفرز'!B4 -> D31-1R | J4: ='ملخص الفرز'!C4 -> 579 | K4: ='ملخص الفرز'!F4 -> 775 | L4: =K4-J4 -> 196
A5: DC38 | B5: ='ملخص الفرز'!I5 -> 1860 | C5: 1926 | D5: =C5-B5 -> 66 | H5: 4 | I5: ='ملخص الفرز'!B5 -> D31-2R | J5: ='ملخص الفرز'!C5 -> 726 | K5: ='ملخص الفرز'!F5 -> 925 | L5: =K5-J5 -> 199
A6: DC39 | B6: ='ملخص الفرز'!I6 -> 795 | C6: 840 | D6: =C6-B6 -> 45 | H6: 5 | I6: ='ملخص الفرز'!B6 -> D31-3R | J6: ='ملخص الفرز'!C6 -> 762 | K6: ='ملخص الفرز'!F6 -> 925 | L6: =K6-J6 -> 163
A7: Dc40 | B7: ='ملخص الفرز'!I7 -> 1875 | C7: 1920 | D7: =C7-B7 -> 45 | H7: 6 | I7: ='ملخص الفرز'!B7 -> D31-4R | J7: ='ملخص الفرز'!C7 -> 768 | K7: ='ملخص الفرز'!F7 -> 925 | L7: =K7-J7 -> 157
A8: BRG9 | B8: ='ملخص الفرز'!I8 -> 1122 | C8: 1150 | D8: =C8-B8 -> 28 | H8: 7 | I8: ='ملخص الفرز'!B8 -> D32-3R | J8: ='ملخص الفرز'!C8 -> 885 | K8: ='ملخص الفرز'!F8 -> 925 | L8: =K8-J8 -> 40
A9: BRG10 | B9: 2605 | C9: 2775 | D9: =C9-B9 -> 170 | H9: 8 | I9: ='ملخص الفرز'!B9 -> D33-1L | J9: ='ملخص الفرز'!C9 -> 825 | K9: ='ملخص الفرز'!F9 -> 925 | L9: =K9-J9 -> 100
A10: BRG11 | B10: ='ملخص الفرز'!L2 -> 2898 | C10: 2950 | D10: =C10-B10 -> 52 | H10: 9 | I10: ='ملخص الفرز'!B10 -> D33-2L | J10: ='ملخص الفرز'!C10 -> 897 | K10: ='ملخص الفرز'!F10 -> 925 | L10: =K10-J10 -> 28
A11: Brg 12 | B11: ='ملخص الفرز'!L3 -> 5622 | C11: 5780 | D11: =C11-B11 -> 158 | H11: 10 | I11: ='ملخص الفرز'!B11 -> D33-3L | J11: ='ملخص الفرز'!C11 -> 888 | K11: ='ملخص الفرز'!F11 -> 925 | L11: =K11-J11 -> 37
H12: 11 | I12: ='ملخص الفرز'!B12 -> D33-4L | J12: ='ملخص الفرز'!C12 -> 1335 | K12: ='ملخص الفرز'!F12 -> 1460 | L12: =K12-J12 -> 125
H13: 12 | I13: ='ملخص الفرز'!B13 -> D34-1L | J13: ='ملخص الفرز'!C13 -> 900 | K13: ='ملخص الفرز'!F13 -> 925 | L13: =K13-J13 -> 25
A14: القناة الموزعة | B14: المقطع | C14: طول التبطين | D14: المحيط | E14: المساحه M² | H14: 13 | I14: ='ملخص الفرز'!B14 -> D34-1R | J14: ='ملخص الفرز'!C14 -> 822 | K14: ='ملخص الفرز'!F14 -> 925 | L14: =K14-J14 -> 103
A15: DC34 | B15: 0-670 | C15: 660 | D15: 3.3436 | E15: =D15*C15 -> 2206.776 | H15: 14 | I15: ='ملخص الفرز'!B15 -> D34-2L | J15: ='ملخص الفرز'!C15 -> 903 | K15: ='ملخص الفرز'!F15 -> 925 | L15: =K15-J15 -> 22
B16: 690-1750 | C16: =B2-C15 -> 1083 | D16: 2.983 | E16: =D16*C16 -> 3230.589 | H16: 15 | I16: ='ملخص الفرز'!B16 -> D34-2R | J16: ='ملخص الفرز'!C16 -> 894 | K16: ='ملخص الفرز'!F16 -> 925 | L16: =K16-J16 -> 31
A17: DC35 | B17: 1 | C17: =B3 -> 564 | D17: 2.98 | E17: =D17*C17 -> 1680.72 | H17: 16 | I17: ='ملخص الفرز'!B17 -> D34-3L | J17: ='ملخص الفرز'!C17 -> 915 | K17: ='ملخص الفرز'!F17 -> 925 | L17: =K17-J17 -> 10
A18: DC36 | B18: 1 | C18: =B4 -> 363 | D18: 2.98 | E18: =D18*C18 -> 1081.74 | H18: 17 | I18: ='ملخص الفرز'!B18 -> D34-3R | J18: ='ملخص الفرز'!C18 -> 867 | K18: ='ملخص الفرز'!F18 -> 925 | L18: =K18-J18 -> 58
A19: DC38 | B19: 1 | C19: =B5 -> 1860 | D19: 3.06 | E19: =D19*C19 -> 5691.6 | H19: 18 | I19: ='ملخص الفرز'!B19 -> D34-4L | J19: ='ملخص الفرز'!C19 -> 561 | K19: ='ملخص الفرز'!F19 -> 560 | L19: =K19-J19 -> -1
A20: DC39 | B20: 1 | C20: =B6 -> 795 | D20: 2.98 | E20: =D20*C20 -> 2369.1 | H20: 19 | I20: ='ملخص الفرز'!B20 -> D34-4R | J20: ='ملخص الفرز'!C20 -> 876 | K20: ='ملخص الفرز'!F20 -> 925 | L20: =K20-J20 -> 49
A21: Dc40 | B21: 0-840 | C21: =792+9 -> 801 | D21: 3.68 | E21: =D21*C21 -> 2947.68 | H21: 20 | I21: ='ملخص الفرز'!B21 -> D35-1L | J21: ='ملخص الفرز'!C21 -> 987 | K21: ='ملخص الفرز'!F21 -> 1050 | L21: =K21-J21 -> 63
B22: 840-END | C22: =B7-C21 -> 1074 | D22: 3.06 | E22: =D22*C22 -> 3286.44 | H22: 21 | I22: ='ملخص الفرز'!B22 -> D35-1R | J22: ='ملخص الفرز'!C22 -> 783 | K22: ='ملخص الفرز'!F22 -> 925 | L22: =K22-J22 -> 142
A23: BRG9 | B23: 1 | C23: =B8 -> 1122 | D23: 4.4648 | E23: =D23*C23 -> 5009.5056 | H23: 22 | I23: ='ملخص الفرز'!B23 -> D35-2R | J23: ='ملخص الفرز'!C23 -> 885 | K23: ='ملخص الفرز'!F23 -> 925 | L23: =K23-J23 -> 40
A24: BRG10 | B24: 1 | C24: =B9 -> 2605 | D24: 3.52 | E24: =D24*C24 -> 9169.6 | H24: 23 | I24: ='ملخص الفرز'!B24 -> D35-3R | J24: ='ملخص الفرز'!C24 -> 1152 | K24: ='ملخص الفرز'!F24 -> 1200 | L24: =K24-J24 -> 48
E25: =SUM(E15:E24) -> 36673.751 | H25: 24 | I25: ='ملخص الفرز'!B25 -> D36-1L | J25: ='ملخص الفرز'!C25 -> 540 | K25: ='ملخص الفرز'!F25 -> 550 | L25: =K25-J25 -> 10
H26: 25 | I26: ='ملخص الفرز'!B26 -> D36-2L | J26: ='ملخص الفرز'!C26 -> 906 | K26: ='ملخص الفرز'!F26 -> 1030 | L26: =K26-J26 -> 124
H27: 26 | I27: ='ملخص الفرز'!B27 -> D37-1L | J27: ='ملخص الفرز'!C27 -> 927 | K27: ='ملخص الفرز'!F27 -> 925 | L27: =K27-J27 -> -2
H28: 27 | I28: ='ملخص الفرز'!B28 -> D37-1R | J28: ='ملخص الفرز'!C28 -> 897 | K28: ='ملخص الفرز'!F28 -> 925 | L28: =K28-J28 -> 28
H29: 28 | I29: ='ملخص الفرز'!B29 -> D37-2L | J29: ='ملخص الفرز'!C29 -> 930 | K29: ='ملخص الفرز'!F29 -> 925 | L29: =K29-J29 -> -5
H30: 29 | I30: ='ملخص الفرز'!B30 -> D37-2R | J30: ='ملخص الفرز'!C30 -> 924 | K30: ='ملخص الفرز'!F30 -> 925 | L30: =K30-J30 -> 1
H31: 30 | I31: ='ملخص الفرز'!B31 -> D38-1L | J31: ='ملخص الفرز'!C31 -> 912 | K31: ='ملخص الفرز'!F31 -> 925 | L31: =K31-J31 -> 13
H32: 31 | I32: ='ملخص الفرز'!B32 -> D38-2L | J32: ='ملخص الفرز'!C32 -> 909 | K32: ='ملخص الفرز'!F32 -> 1000 | L32: =K32-J32 -> 91
A33: القناة الفرعية | B33: المقطع | C33: طول التبطين | D33: المحيط | E33: المساحه M² | H33: 32 | I33: ='ملخص الفرز'!B33 -> D38-3L | J33: ='ملخص الفرز'!C33 -> 1395 | K33: ='ملخص الفرز'!F33 -> 1460 | L33: =K33-J33 -> 65
A34: BRG11 | B34: 1100-2500 | C34: =466*3 -> 1398 | D34: 5.1 | E34: =D34*C34 -> 7129.8 | H34: 33 | I34: ='ملخص الفرز'!B34 -> D39-1R | J34: ='ملخص الفرز'!C34 -> 822 | K34: ='ملخص الفرز'!F34 -> 925 | L34: =K34-J34 -> 103
B35: 2500-3900 | C35: =B10-C34 -> 1500 | D35: 3.98 | E35: =D35*C35 -> 5970 | H35: 34 | I35: ='ملخص الفرز'!B35 -> D39-2R | J35: ='ملخص الفرز'!C35 -> 825 | K35: ='ملخص الفرز'!F35 -> 925 | L35: =K35-J35 -> 100
A36: BRG 12 | B36: 1 | C36: 3261 | D36: 6.451 | E36: =D36*C36 -> 21036.711 | H36: 35 | I36: ='ملخص الفرز'!B36 -> D39-3R | J36: ='ملخص الفرز'!C36 -> 1413 | K36: ='ملخص الفرز'!F36 -> 1465 | L36: =K36-J36 -> 52
B37: 2 | C37: =B11-C36 -> 2361 | D37: 4.72 | E37: =D37*C37 -> 11143.92 | H37: 36 | I37: ='ملخص الفرز'!B37 -> D40-1L | J37: ='ملخص الفرز'!C37 -> 645 | K37: ='ملخص الفرز'!F37 -> 775 | L37: =K37-J37 -> 130
E38: =SUM(E34:E37) -> 45280.431 | H38: 37 | I38: ='ملخص الفرز'!B38 -> D40-1R | J38: ='ملخص الفرز'!C38 -> 663 | K38: ='ملخص الفرز'!F38 -> 975 | L38: =K38-J38 -> 312
H39: 38 | I39: ='ملخص الفرز'!B39 -> D40-2L | J39: ='ملخص الفرز'!C39 -> 831 | K39: ='ملخص الفرز'!F39 -> 875 | L39: =K39-J39 -> 44
H40: 39 | I40: ='ملخص الفرز'!B40 -> D40-2L-1 | J40: ='ملخص الفرز'!C40 -> 981 | K40: ='ملخص الفرز'!F40 -> 1050 | L40: =K40-J40 -> 69
...

Sheet Concrete Orders
L3: 45861 | M3: حساب الكمية لتاريخ
K4: =sum(K7:K1054) -> 12951 | L4: =(K4+O4)*3 -> 76905 | M4: مجموع الطول | O4: =sum(O7:O1054) -> 12684
A5: الفاشل | B5: رقم السلفة | C5: التسلسل | D5: تاريخ الصب | E5: بعد 7 ايام | F5: بعد 28 يوم | G5: التفاصيل | H5: Panels | J5: عدد | K5: عدد | L5: Betweens | N5: عدد | O5: عدد | P5: رقم الاوردر | Q5: الكدس | R5: الكمية
H6: من | I6: الى | L6: من | M6: الى
A7: Y | B7: 2 | C7: 1 to 6 | D7: 45557 | E7: =D7+7 -> 45564 | F7: =D7+28 -> 45585 | G7: D34-1L | H7: 1 | I7: 29 | J7: =if(ISBLANK(H7),"",(((I7-H7)/2)+1)) -> 15 | K7: =if($D7<=$L$3,J7,0) -> 15 | N7: =if(ISBLANK(L7),"",(((M7-L7)/2)+1)) | O7: =if($D7<=$L$3,N7,0)
A8: Y | B8: 2 | C8: 73 TO 78 | D8: 45574 | E8: =D8+7 -> 45581 | F8: =D8+28 -> 45602 | G8: D36-1L | H8: 1 | I8: 157 | J8: =if(ISBLANK(H8),"",(((I8-H8)/2)+1)) -> 79 | K8: =if($D8<=$L$3,J8,0) -> 79 | N8: =if(ISBLANK(L8),"",(((M8-L8)/2)+1)) | O8: =if($D8<=$L$3,N8,0)
A9: Y | B9: 2 | C9: 91-96 | D9: 45575 | E9: =D9+7 -> 45582 | F9: =D9+28 -> 45603 | G9: D36-1L | H9: 159 | I9: 177 | J9: =if(ISBLANK(H9),"",(((I9-H9)/2)+1)) -> 10 | K9: =if($D9<=$L$3,J9,0) -> 10 | N9: =if(ISBLANK(L9),"",(((M9-L9)/2)+1)) | O9: =if($D9<=$L$3,N9,0)
A10: Y | B10: 2 | C10: 91-96 | D10: 45575 | E10: =D10+7 -> 45582 | F10: =D10+28 -> 45603 | G10: D36-2L | H10: 1 | I10: 161 | J10: =if(ISBLANK(H10),"",(((I10-H10)/2)+1)) -> 81 | K10: =if($D10<=$L$3,J10,0) -> 81 | N10: =if(ISBLANK(L10),"",(((M10-L10)/2)+1)) | O10: =if($D10<=$L$3,N10,0)
A11: Y | B11: 2 | C11: 109-114 | D11: 45577 | E11: =D11+7 -> 45584 | F11: =D11+28 -> 45605 | G11: D36-1L | J11: =if(ISBLANK(H11),"",(((I11-H11)/2)+1)) | K11: =if($D11<=$L$3,J11,0) | L11: 2 | M11: 178 | N11: =if(ISBLANK(L11),"",(((M11-L11)/2)+1)) -> 89 | O11: =if($D11<=$L$3,N11,0) -> 89
A12: Y | B12: 2 | C12: 109-114 | D12: 45577 | E12: =D12+7 -> 45584 | F12: =D12+28 -> 45605 | G12: D36-2L | J12: =if(ISBLANK(H12),"",(((I12-H12)/2)+1)) | K12: =if($D12<=$L$3,J12,0) | L12: 2 | M12: 24 | N12: =if(ISBLANK(L12),"",(((M12-L12)/2)+1)) -> 12 | O12: =if($D12<=$L$3,N12,0) -> 12
A13: Y | B13: 2 | C13: 115-120 | D13: 45578 | E13: =D13+7 -> 45585 | F13: =D13+28 -> 45606 | G13: D36-2L | H13: 163 | I13: 347 | J13: =if(ISBLANK(H13),"",(((I13-H13)/2)+1)) -> 93 | K13: =if($D13<=$L$3,J13,0) -> 93 | N13: =if(ISBLANK(L13),"",(((M13-L13)/2)+1)) | O13: =if($D13<=$L$3,N13,0)
A14: Y | B14: 2 | C14: 127-132 | D14: 45579 | E14: =D14+7 -> 45586 | F14: =D14+28 -> 45607 | G14: D34-1L | H14: 31 | I14: 183 | J14: =if(ISBLANK(H14),"",(((I14-H14)/2)+1)) -> 77 | K14: =if($D14<=$L$3,J14,0) -> 77 | N14: =if(ISBLANK(L14),"",(((M14-L14)/2)+1)) | O14: =if($D14<=$L$3,N14,0)
A15: Y | B15: 2 | C15: 133-138 | D15: 45579 | E15: =D15+7 -> 45586 | F15: =D15+28 -> 45607 | G15: D36-2L | J15: =if(ISBLANK(H15),"",(((I15-H15)/2)+1)) | K15: =if($D15<=$L$3,J15,0) | L15: 26 | M15: 220 | N15: =if(ISBLANK(L15),"",(((M15-L15)/2)+1)) -> 98 | O15: =if($D15<=$L$3,N15,0) -> 98
A16: Y | B16: 2 | C16: 151-156 | D16: 45580 | E16: =D16+7 -> 45587 | F16: =D16+28 -> 45608 | G16: D34-1L | H16: 185 | I16: 299 | J16: =if(ISBLANK(H16),"",(((I16-H16)/2)+1)) -> 58 | K16: =if($D16<=$L$3,J16,0) -> 58 | N16: =if(ISBLANK(L16),"",(((M16-L16)/2)+1)) | O16: =if($D16<=$L$3,N16,0)
A17: Y | B17: 2 | C17: 151-156 | D17: 45580 | E17: =D17+7 -> 45587 | F17: =D17+28 -> 45608 | G17: D34-1L | J17: =if(ISBLANK(H17),"",(((I17-H17)/2)+1)) | K17: =if($D17<=$L$3,J17,0) | L17: 4 | M17: 8 | N17: =if(ISBLANK(L17),"",(((M17-L17)/2)+1)) -> 3 | O17: =if($D17<=$L$3,N17,0) -> 3
A18: Y | B18: 2 | C18: 157-162 | D18: 45580 | E18: =D18+7 -> 45587 | F18: =D18+28 -> 45608 | G18: D36-2L | J18: =if(ISBLANK(H18),"",(((I18-H18)/2)+1)) | K18: =if($D18<=$L$3,J18,0) | L18: 220 | M18: 248 | N18: =if(ISBLANK(L18),"",(((M18-L18)/2)+1)) -> 15 | O18: =if($D18<=$L$3,N18,0) -> 15
A19: Y | B19: 2 | C19: 169-174 | D19: 45581 | E19: =D19+7 -> 45588 | F19: =D19+28 -> 45609 | G19: D34-1L | J19: =if(ISBLANK(H19),"",(((I19-H19)/2)+1)) | K19: =if($D19<=$L$3,J19,0) | L19: 10 | M19: 180 | N19: =if(ISBLANK(L19),"",(((M19-L19)/2)+1)) -> 86 | O19: =if($D19<=$L$3,N19,0) -> 86
A20: Y | B20: 2 | C20: 187-192 | D20: 45582 | E20: =D20+7 -> 45589 | F20: =D20+28 -> 45610 | G20: D34-2L | H20: 1 | I20: 201 | J20: =if(ISBLANK(H20),"",(((I20-H20)/2)+1)) -> 101 | K20: =if($D20<=$L$3,J20,0) -> 101 | N20: =if(ISBLANK(L20),"",(((M20-L20)/2)+1)) | O20: =if($D20<=$L$3,N20,0)
A21: Y | B21: 2 | C21: 205-210 | D21: 45584 | E21: =D21+7 -> 45591 | F21: =D21+28 -> 45612 | G21: D34-2L | J21: =if(ISBLANK(H21),"",(((I21-H21)/2)+1)) | K21: =if($D21<=$L$3,J21,0) | L21: 2 | M21: 104 | N21: =if(ISBLANK(L21),"",(((M21-L21)/2)+1)) -> 52 | O21: =if($D21<=$L$3,N21,0) -> 52
A22: Y | B22: 2 | C22: 205-210 | D22: 45584 | E22: =D22+7 -> 45591 | F22: =D22+28 -> 45612 | G22: D34-2L | H22: 203 | I22: 255 | J22: =if(ISBLANK(H22),"",(((I22-H22)/2)+1)) -> 27 | K22: =if($D22<=$L$3,J22,0) -> 27 | N22: =if(ISBLANK(L22),"",(((M22-L22)/2)+1)) | O22: =if($D22<=$L$3,N22,0)
A23: Y | B23: 2 | C23: 217-222 | D23: 45585 | E23: =D23+7 -> 45592 | F23: =D23+28 -> 45613 | G23: D34-2L | H23: 257 | I23: 299 | J23: =if(ISBLANK(H23),"",(((I23-H23)/2)+1)) -> 22 | K23: =if($D23<=$L$3,J23,0) -> 22 | N23: =if(ISBLANK(L23),"",(((M23-L23)/2)+1)) | O23: =if($D23<=$L$3,N23,0)
A24: Y | B24: 2 | C24: 217-222 | D24: 45585 | E24: =D24+7 -> 45592 | F24: =D24+28 -> 45613 | G24: D34-2L | J24: =if(ISBLANK(H24),"",(((I24-H24)/2)+1)) | K24: =if($D24<=$L$3,J24,0) | L24: 106 | M24: 254 | N24: =if(ISBLANK(L24),"",(((M24-L24)/2)+1)) -> 75 | O24: =if($D24<=$L$3,N24,0) -> 75
A25: Y | B25: 2 | C25: 229-234 | D25: 45586 | E25: =D25+7 -> 45593 | F25: =D25+28 -> 45614 | G25: D34-2R | H25: 1 | I25: 201 | J25: =if(ISBLANK(H25),"",(((I25-H25)/2)+1)) -> 101 | K25: =if($D25<=$L$3,J25,0) -> 101 | N25: =if(ISBLANK(L25),"",(((M25-L25)/2)+1)) | O25: =if($D25<=$L$3,N25,0)
A26: Y | B26: 2 | C26: 241-246 | D26: 45587 | E26: =D26+7 -> 45594 | F26: =D26+28 -> 45615 | G26: D34-2R | J26: =if(ISBLANK(H26),"",(((I26-H26)/2)+1)) | K26: =if($D26<=$L$3,J26,0) | L26: 2 | M26: 160 | N26: =if(ISBLANK(L26),"",(((M26-L26)/2)+1)) -> 80 | O26: =if($D26<=$L$3,N26,0) -> 80
A27: Y | B27: 2 | C27: 241-246 | D27: 45587 | E27: =D27+7 -> 45594 | F27: =D27+28 -> 45615 | G27: D34-2L | J27: =if(ISBLANK(H27),"",(((I27-H27)/2)+1)) | K27: =if($D27<=$L$3,J27,0) | L27: 256 | M27: 298 | N27: =if(ISBLANK(L27),"",(((M27-L27)/2)+1)) -> 22 | O27: =if($D27<=$L$3,N27,0) -> 22
A28: Y | B28: 2 | C28: 253-258 | D28: 45588 | E28: =D28+7 -> 45595 | F28: =D28+28 -> 45616 | G28: D34-1L | J28: =if(ISBLANK(H28),"",(((I28-H28)/2)+1)) | K28: =if($D28<=$L$3,J28,0) | L28: 182 | M28: 266 | N28: =if(ISBLANK(L28),"",(((M28-L28)/2)+1)) -> 43 | O28: =if($D28<=$L$3,N28,0) -> 43
A29: Y | B29: 2 | C29: 253-258 | D29: 45588 | E29: =D29+7 -> 45595 | F29: =D29+28 -> 45616 | G29: D34-1R | H29: 1 | I29: 77 | J29: =if(ISBLANK(H29),"",(((I29-H29)/2)+1)) -> 39 | K29: =if($D29<=$L$3,J29,0) -> 39 | N29: =if(ISBLANK(L29),"",(((M29-L29)/2)+1)) | O29: =if($D29<=$L$3,N29,0)
A30: Y | B30: 2 | C30: 265-270 | D30: 45589 | E30: =D30+7 -> 45596 | F30: =D30+28 -> 45617 | G30: D34-1R | H30: 79 | I30: 159 | J30: =if(ISBLANK(H30),"",(((I30-H30)/2)+1)) -> 41 | K30: =if($D30<=$L$3,J30,0) -> 41 | N30: =if(ISBLANK(L30),"",(((M30-L30)/2)+1)) | O30: =if($D30<=$L$3,N30,0)
A31: Y | B31: 2 | C31: 265-270 | D31: 45589 | E31: =D31+7 -> 45596 | F31: =D31+28 -> 45617 | G31: D34-2R | H31: 211 | I31: 293 | J31: =if(ISBLANK(H31),"",(((I31-H31)/2)+1)) -> 42 | K31: =if($D31<=$L$3,J31,0) -> 42 | N31: =if(ISBLANK(L31),"",(((M31-L31)/2)+1)) | O31: =if($D31<=$L$3,N31,0)
A32: Y | B32: 2 | C32: 277-282 | D32: 45592 | E32: =D32+7 -> 45599 | F32: =D32+28 -> 45620 | G32: D34-1R | J32: =if(ISBLANK(H32),"",(((I32-H32)/2)+1)) | K32: =if($D32<=$L$3,J32,0) | L32: 2 | M32: 58 | N32: =if(ISBLANK(L32),"",(((M32-L32)/2)+1)) -> 29 | O32: =if($D32<=$L$3,N32,0) -> 29
A33: Y | B33: 2 | C33: 277-282 | D33: 45592 | E33: =D33+7 -> 45599 | F33: =D33+28 -> 45620 | G33: D34-1R | H33: 161 | I33: 229 | J33: =if(ISBLANK(H33),"",(((I33-H33)/2)+1)) -> 35 | K33: =if($D33<=$L$3,J33,0) -> 35 | N33: =if(ISBLANK(L33),"",(((M33-L33)/2)+1)) | O33: =if($D33<=$L$3,N33,0)
A34: Y | B34: 2 | C34: 277-282 | D34: 45592 | E34: =D34+7 -> 45599 | F34: =D34+28 -> 45620 | G34: D34-1R | H34: 243 | I34: 275 | J34: =if(ISBLANK(H34),"",(((I34-H34)/2)+1)) -> 17 | K34: =if($D34<=$L$3,J34,0) -> 17 | N34: =if(ISBLANK(L34),"",(((M34-L34)/2)+1)) | O34: =if($D34<=$L$3,N34,0)
A35: Y | B35: 2 | C35: 283-288 | D35: 45593 | E35: =D35+7 -> 45600 | F35: =D35+28 -> 45621 | G35: D34-1R | H35: 277 | I35: 291 | J35: =if(ISBLANK(H35),"",(((I35-H35)/2)+1)) -> 8 | K35: =if($D35<=$L$3,J35,0) -> 8 | L35: 60 | M35: 268 | N35: =if(ISBLANK(L35),"",(((M35-L35)/2)+1)) -> 105 | O35: =if($D35<=$L$3,N35,0) -> 105
A36: Y | B36: 2 | C36: 289-294 | D36: 45594 | E36: =D36+7 -> 45601 | F36: =D36+28 -> 45622 | G36: D34-3R | H36: 9 | I36: 95 | J36: =if(ISBLANK(H36),"",(((I36-H36)/2)+1)) -> 44 | K36: =if($D36<=$L$3,J36,0) -> 44 | N36: =if(ISBLANK(L36),"",(((M36-L36)/2)+1)) | O36: =if($D36<=$L$3,N36,0)
A37: Y | B37: 2 | C37: 289-294 | D37: 45594 | E37: =D37+7 -> 45601 | F37: =D37+28 -> 45622 | G37: D34-2R | H37: 295 | I37: 297 | J37: =if(ISBLANK(H37),"",(((I37-H37)/2)+1)) -> 2 | K37: =if($D37<=$L$3,J37,0) -> 2 | L37: 162 | M37: 200 | N37: =if(ISBLANK(L37),"",(((M37-L37)/2)+1)) -> 20 | O37: =if($D37<=$L$3,N37,0) -> 20
A38: Y | B38: 2 | C38: 289-294 | D38: 45594 | E38: =D38+7 -> 45601 | F38: =D38+28 -> 45622 | G38: D34-2R | J38: =if(ISBLANK(H38),"",(((I38-H38)/2)+1)) | K38: =if($D38<=$L$3,J38,0) | L38: 212 | M38: 292 | N38: =if(ISBLANK(L38),"",(((M38-L38)/2)+1)) -> 41 | O38: =if($D38<=$L$3,N38,0) -> 41
A39: Y | B39: 2 | C39: 295-300 | D39: 45595 | E39: =D39+7 -> 45602 | F39: =D39+28 -> 45623 | G39: D34-3R | H39: 97 | I39: 147 | J39: =if(ISBLANK(H39),"",(((I39-H39)/2)+1)) -> 26 | K39: =if($D39<=$L$3,J39,0) -> 26 | L39: 10 | M39: 46 | N39: =if(ISBLANK(L39),"",(((M39-L39)/2)+1)) -> 19 | O39: =if($D39<=$L$3,N39,0) -> 19
A40: Y | B40: 2 | C40: 295-300 | D40: 45595 | E40: =D40+7 -> 45602 | F40: =D40+28 -> 45623 | G40: D34-3R | H40: 159 | I40: 303 | J40: =if(ISBLANK(H40),"",(((I40-H40)/2)+1)) -> 73 | K40: =if($D40<=$L$3,J40,0) -> 73 | N40: =if(ISBLANK(L40),"",(((M40-L40)/2)+1)) | O40: =if($D40<=$L$3,N40,0)
A41: Y | B41: 2 | C41: 307 to 312 | D41: 45596 | E41: =D41+7 -> 45603 | F41: =D41+28 -> 45624 | G41: D34-3R | J41: =if(ISBLANK(H41),"",(((I41-H41)/2)+1)) | K41: =if($D41<=$L$3,J41,0) | L41: 48 | M41: 146 | N41: =if(ISBLANK(L41),"",(((M41-L41)/2)+1)) -> 50 | O41: =if($D41<=$L$3,N41,0) -> 50
A42: Y | B42: 2 | C42: 307 to 312 | D42: 45596 | E42: =D42+7 -> 45603 | F42: =D42+28 -> 45624 | G42: D34-3R | J42: =if(ISBLANK(H42),"",(((I42-H42)/2)+1)) | K42: =if($D42<=$L$3,J42,0) | L42: 160 | M42: 304 | N42: =if(ISBLANK(L42),"",(((M42-L42)/2)+1)) -> 73 | O42: =if($D42<=$L$3,N42,0) -> 73
...

Sheet صفحة الفرز
E1: نتائج متوفرة؟ | F1: اسم القناة | G1: رقم السلفة
A2: من | B2: 45414 | C2: الى | D2: 45864 | E2: الكل | F2: الكل | G2: الكل | K2: =H2+M2 -> 0 | AA2: =sum(AB:AB) -> 212463 | AC2: D40-1L | AD2: =AA2+AF2 -> 225193 | AE2: =AB2+AG2 -> 0 | AF2: =sum(AG:AG) -> 12730
F3: =(SUM(J9:J1945)+SUM(N9:N1945))*3 -> 77271 | G3: طول التبطين | K3: =K2*3 -> 0 | AD3: =AD2*3 -> 675579 | AE3: =AE2*3 -> 0
A7: =IFERROR(__xludf.DUMMYFUNCTION("{ 'Concrete Orders'!A5:R6; QUERY('Concrete Orders'!A:R, ""select * where D >= date '""&TEXT(B2,""yyyy-mm-dd"")&""' and D <= date '""&TEXT(D2,""yyyy-mm-dd"")&""' ""&IF(E2=""الكل"", """", ""and A = '""&E2&""' "")&"" ""&IF(F2=""الكل"", """&""", ""and G = '""&F2&""' "")&"" ""&IF(G2=""الكل"", """", ""and B = '""&G2&""' "")&"" ORDER BY D"", 1) } "),"الفاشل") -> الفاشل | B7: =IFERROR(__xludf.DUMMYFUNCTION("""COMPUTED_VALUE"""),"رقم السلفة") -> رقم السلفة | C7: =IFERROR(__xludf.DUMMYFUNCTION("""COMPUTED_VALUE"""),"التسلسل") -> التسلسل | D7: =IFERROR(__xludf.DUMMYFUNCTION("""COMPUTED_VALUE"""),"تاريخ الصب") -> تاريخ الصب | E7: =IFERROR(__xludf.DUMMYFUNCTION("""COMPUTED_VALUE"""),"بعد 7 ايام") -> بعد 7 ايام | F7: =IFERROR(__xludf.DUMMYFUNCTION("""COMPUTED_VALUE"""),"بعد 28 يوم") -> بعد 28 يوم | G7: =IFERROR(__xludf.DUMMYFUNCTION("""COMPUTED_VALUE"""),"التفاصيل") -> التفاصيل | H7: =IFERROR(__xludf.DUMMYFUNCTION("""COMPUTED_VALUE"""),"Panels") -> Panels | J7: =IFERROR(__xludf.DUMMYFUNCTION("""COMPUTED_VALUE"""),"عدد") -> عدد | K7: =IFERROR(__xludf.DUMMYFUNCTION("""COMPUTED_VALUE"""),"عدد") -> عدد | L7: =IFERROR(__xludf.DUMMYFUNCTION("""COMPUTED_VALUE"""),"Betweens") -> Betweens | N7: =IFERROR(__xludf.DUMMYFUNCTION("""COMPUTED_VALUE"""),"عدد") -> عدد | O7: =IFERROR(__xludf.DUMMYFUNCTION("""COMPUTED_VALUE"""),"عدد") -> عدد | P7: =IFERROR(__xludf.DUMMYFUNCTION("""COMPUTED_VALUE"""),"رقم الاوردر") -> رقم الاوردر | Q7: =IFERROR(__xludf.DUMMYFUNCTION("""COMPUTED_VALUE"""),"الكدس") -> الكدس | R7: =IFERROR(__xludf.DUMMYFUNCTION("""COMPUTED_VALUE"""),"الكمية") -> الكمية
H8: =IFERROR(__xludf.DUMMYFUNCTION("""COMPUTED_VALUE"""),"من") -> من | I8: =IFERROR(__xludf.DUMMYFUNCTION("""COMPUTED_VALUE"""),"الى ") -> الى | L8: =IFERROR(__xludf.DUMMYFUNCTION("""COMPUTED_VALUE"""),"من") -> من | M8: =IFERROR(__xludf.DUMMYFUNCTION("""COMPUTED_VALUE"""),"الى ") -> الى | T8: =IFERROR(__xludf.DUMMYFUNCTION("QUERY('Concrete Orders'!A:R, ""select * where D >= date '""&TEXT(B2,""yyyy-mm-dd"")&""' and D <= date '""&TEXT(D2,""yyyy-mm-dd"")&""' ""&IF(E2=""الكل"", """", ""and A = '""&E2&""' "")&"" ""&IF(F2=""الكل"", """", ""and G = '""&F2&""' "")&"" "&" ORDER BY D"", 1)"),"Y") -> Y | U8: =IFERROR(__xludf.DUMMYFUNCTION("""COMPUTED_VALUE"""),"2") -> 2 | V8: =IFERROR(__xludf.DUMMYFUNCTION("""COMPUTED_VALUE"""),"1 to 6") -> 1 to 6 | W8: =IFERROR(__xludf.DUMMYFUNCTION("""COMPUTED_VALUE"""),45557.0) -> 45557 | X8: =IFERROR(__xludf.DUMMYFUNCTION("""COMPUTED_VALUE"""),45564.0) -> 45564 | Y8: =IFERROR(__xludf.DUMMYFUNCTION("""COMPUTED_VALUE"""),45585.0) -> 45585 | Z8: =IFERROR(__xludf.DUMMYFUNCTION("""COMPUTED_VALUE"""),"D34-1L") -> D34-1L | AA8: =IFERROR(__xludf.DUMMYFUNCTION("""COMPUTED_VALUE"""),1.0) -> 1 | AB8: =IFERROR(__xludf.DUMMYFUNCTION("""COMPUTED_VALUE"""),29.0) -> 29 | AC8: =IFERROR(__xludf.DUMMYFUNCTION("""COMPUTED_VALUE"""),15.0) -> 15 | AD8: =IFERROR(__xludf.DUMMYFUNCTION("""COMPUTED_VALUE"""),15.0) -> 15
A9: =IFERROR(__xludf.DUMMYFUNCTION("""COMPUTED_VALUE"""),"Y") -> Y | B9: =IFERROR(__xludf.DUMMYFUNCTION("""COMPUTED_VALUE"""),"2") -> 2 | C9: =IFERROR(__xludf.DUMMYFUNCTION("""COMPUTED_VALUE"""),"1 to 6") -> 1 to 6 | D9: =IFERROR(__xludf.DUMMYFUNCTION("""COMPUTED_VALUE"""),45557.0) -> 45557 | E9: =IFERROR(__xludf.DUMMYFUNCTION("""COMPUTED_VALUE"""),45564.0) -> 45564 | F9: =IFERROR(__xludf.DUMMYFUNCTION("""COMPUTED_VALUE"""),45585.0) -> 45585 | G9: =IFERROR(__xludf.DUMMYFUNCTION("""COMPUTED_VALUE"""),"D34-1L") -> D34-1L | H9: =IFERROR(__xludf.DUMMYFUNCTION("""COMPUTED_VALUE"""),1.0) -> 1 | I9: =IFERROR(__xludf.DUMMYFUNCTION("""COMPUTED_VALUE"""),29.0) -> 29 | J9: =IFERROR(__xludf.DUMMYFUNCTION("""COMPUTED_VALUE"""),15.0) -> 15 | K9: =IFERROR(__xludf.DUMMYFUNCTION("""COMPUTED_VALUE"""),15.0) -> 15 | T9: =IFERROR(__xludf.DUMMYFUNCTION("""COMPUTED_VALUE"""),"Y") -> Y | U9: =IFERROR(__xludf.DUMMYFUNCTION("""COMPUTED_VALUE"""),"2") -> 2 | V9: =IFERROR(__xludf.DUMMYFUNCTION("""COMPUTED_VALUE"""),"73 TO 78") -> 73 TO 78 | W9: =IFERROR(__xludf.DUMMYFUNCTION("""COMPUTED_VALUE"""),45574.0) -> 45574 | X9: =IFERROR(__xludf.DUMMYFUNCTION("""COMPUTED_VALUE"""),45581.0) -> 45581 | Y9: =IFERROR(__xludf.DUMMYFUNCTION("""COMPUTED_VALUE"""),45602.0) -> 45602 | Z9: =IFERROR(__xludf.DUMMYFUNCTION("""COMPUTED_VALUE"""),"D36-1L") -> D36-1L | AA9: =IFERROR(__xludf.DUMMYFUNCTION("""COMPUTED_VALUE"""),1.0) -> 1 | AB9: =IFERROR(__xludf.DUMMYFUNCTION("""COMPUTED_VALUE"""),157.0) -> 157 | AC9: =IFERROR(__xludf.DUMMYFUNCTION("""COMPUTED_VALUE"""),79.0) -> 79 | AD9: =IFERROR(__xludf.DUMMYFUNCTION("""COMPUTED_VALUE"""),79.0) -> 79
A10: =IFERROR(__xludf.DUMMYFUNCTION("""COMPUTED_VALUE"""),"Y") -> Y | B10: =IFERROR(__xludf.DUMMYFUNCTION("""COMPUTED_VALUE"""),"2") -> 2 | C10: =IFERROR(__xludf.DUMMYFUNCTION("""COMPUTED_VALUE"""),"73 TO 78") -> 73 TO 78 | D10: =IFERROR(__xludf.DUMMYFUNCTION("""COMPUTED_VALUE"""),45574.0) -> 45574 | E10: =IFERROR(__xludf.DUMMYFUNCTION("""COMPUTED_VALUE"""),45581.0) -> 45581 | F10: =IFERROR(__xludf.DUMMYFUNCTION("""COMPUTED_VALUE"""),45602.0) -> 45602 | G10: =IFERROR(__xludf.DUMMYFUNCTION("""COMPUTED_VALUE"""),"D36-1L") -> D36-1L | H10: =IFERROR(__xludf.DUMMYFUNCTION("""COMPUTED_VALUE"""),1.0) -> 1 | I10: =IFERROR(__xludf.DUMMYFUNCTION("""COMPUTED_VALUE"""),157.0) -> 157 | J10: =IFERROR(__xludf.DUMMYFUNCTION("""COMPUTED_VALUE"""),79.0) -> 79 | K10: =IFERROR(__xludf.DUMMYFUNCTION("""COMPUTED_VALUE"""),79.0) -> 79 | T10: =IFERROR(__xludf.DUMMYFUNCTION("""COMPUTED_VALUE"""),"Y") -> Y | U10: =IFERROR(__xludf.DUMMYFUNCTION("""COMPUTED_VALUE"""),"2") -> 2 | V10: =IFERROR(__xludf.DUMMYFUNCTION("""COMPUTED_VALUE"""),"91-96") -> 91-96 | W10: =IFERROR(__xludf.DUMMYFUNCTION("""COMPUTED_VALUE"""),45575.0) -> 45575 | X10: =IFERROR(__xludf.DUMMYFUNCTION("""COMPUTED_VALUE"""),45582.0) -> 45582 | Y10: =IFERROR(__xludf.DUMMYFUNCTION("""COMPUTED_VALUE"""),45603.0) -> 45603 | Z10: =IFERROR(__xludf.DUMMYFUNCTION("""COMPUTED_VALUE"""),"D36-1L") -> D36-1L | AA10: =IFERROR(__xludf.DUMMYFUNCTION("""COMPUTED_VALUE"""),159.0) -> 159 | AB10: =IFERROR(__xludf.DUMMYFUNCTION("""COMPUTED_VALUE"""),177.0) -> 177 | AC10: =IFERROR(__xludf.DUMMYFUNCTION("""COMPUTED_VALUE"""),10.0) -> 10 | AD10: =IFERROR(__xludf.DUMMYFUNCTION("""COMPUTED_VALUE"""),10.0) -> 10
A11: =IFERROR(__xludf.DUMMYFUNCTION("""COMPUTED_VALUE"""),"Y") -> Y | B11: =IFERROR(__xludf.DUMMYFUNCTION("""COMPUTED_VALUE"""),"2") -> 2 | C11: =IFERROR(__xludf.DUMMYFUNCTION("""COMPUTED_VALUE"""),"91-96") -> 91-96 | D11: =IFERROR(__xludf.DUMMYFUNCTION("""COMPUTED_VALUE"""),45575.0) -> 45575 | E11: =IFERROR(__xludf.DUMMYFUNCTION("""COMPUTED_VALUE"""),45582.0) -> 45582 | F11: =IFERROR(__xludf.DUMMYFUNCTION("""COMPUTED_VALUE"""),45603.0) -> 45603 | G11: =IFERROR(__xludf.DUMMYFUNCTION("""COMPUTED_VALUE"""),"D36-1L") -> D36-1L | H11: =IFERROR(__xludf.DUMMYFUNCTION("""COMPUTED_VALUE"""),159.0) -> 159 | I11: =IFERROR(__xludf.DUMMYFUNCTION("""COMPUTED_VALUE"""),177.0) -> 177 | J11: =IFERROR(__xludf.DUMMYFUNCTION("""COMPUTED_VALUE"""),10.0) -> 10 | K11: =IFERROR(__xludf.DUMMYFUNCTION("""COMPUTED_VALUE"""),10.0) -> 10 | T11: =IFERROR(__xludf.DUMMYFUNCTION("""COMPUTED_VALUE"""),"Y") -> Y | U11: =IFERROR(__xludf.DUMMYFUNCTION("""COMPUTED_VALUE"""),"2") -> 2 | V11: =IFERROR(__xludf.DUMMYFUNCTION("""COMPUTED_VALUE"""),"91-96") -> 91-96 | W11: =IFERROR(__xludf.DUMMYFUNCTION("""COMPUTED_VALUE"""),45575.0) -> 45575 | X11: =IFERROR(__xludf.DUMMYFUNCTION("""COMPUTED_VALUE"""),45582.0) -> 45582 | Y11: =IFERROR(__xludf.DUMMYFUNCTION("""COMPUTED_VALUE"""),45603.0) -> 45603 | Z11: =IFERROR(__xludf.DUMMYFUNCTION("""COMPUTED_VALUE"""),"D36-2L") -> D36-2L | AA11: =IFERROR(__xludf.DUMMYFUNCTION("""COMPUTED_VALUE"""),1.0) -> 1 | AB11: =IFERROR(__xludf.DUMMYFUNCTION("""COMPUTED_VALUE"""),161.0) -> 161 | AC11: =IFERROR(__xludf.DUMMYFUNCTION("""COMPUTED_VALUE"""),81.0) -> 81 | AD11: =IFERROR(__xludf.DUMMYFUNCTION("""COMPUTED_VALUE"""),81.0) -> 81
A12: =IFERROR(__xludf.DUMMYFUNCTION("""COMPUTED_VALUE"""),"Y") -> Y | B12: =IFERROR(__xludf.DUMMYFUNCTION("""COMPUTED_VALUE"""),"2") -> 2 | C12: =IFERROR(__xludf.DUMMYFUNCTION("""COMPUTED_VALUE"""),"91-96") -> 91-96 | D12: =IFERROR(__xludf.DUMMYFUNCTION("""COMPUTED_VALUE"""),45575.0) -> 45575 | E12: =IFERROR(__xludf.DUMMYFUNCTION("""COMPUTED_VALUE"""),45582.0) -> 45582 | F12: =IFERROR(__xludf.DUMMYFUNCTION("""COMPUTED_VALUE"""),45603.0) -> 45603 | G12: =IFERROR(__xludf.DUMMYFUNCTION("""COMPUTED_VALUE"""),"D36-2L") -> D36-2L | H12: =IFERROR(__xludf.DUMMYFUNCTION("""COMPUTED_VALUE"""),1.0) -> 1 | I12: =IFERROR(__xludf.DUMMYFUNCTION("""COMPUTED_VALUE"""),161.0) -> 161 | J12: =IFERROR(__xludf.DUMMYFUNCTION("""COMPUTED_VALUE"""),81.0) -> 81 | K12: =IFERROR(__xludf.DUMMYFUNCTION("""COMPUTED_VALUE"""),81.0) -> 81 | T12: =IFERROR(__xludf.DUMMYFUNCTION("""COMPUTED_VALUE"""),"Y") -> Y | U12: =IFERROR(__xludf.DUMMYFUNCTION("""COMPUTED_VALUE"""),"2") -> 2 | V12: =IFERROR(__xludf.DUMMYFUNCTION("""COMPUTED_VALUE"""),"109-114") -> 109-114 | W12: =IFERROR(__xludf.DUMMYFUNCTION("""COMPUTED_VALUE"""),45577.0) -> 45577 | X12: =IFERROR(__xludf.DUMMYFUNCTION("""COMPUTED_VALUE"""),45584.0) -> 45584 | Y12: =IFERROR(__xludf.DUMMYFUNCTION("""COMPUTED_VALUE"""),45605.0) -> 45605 | Z12: =IFERROR(__xludf.DUMMYFUNCTION("""COMPUTED_VALUE"""),"D36-1L") -> D36-1L | AE12: =IFERROR(__xludf.DUMMYFUNCTION("""COMPUTED_VALUE"""),2.0) -> 2 | AF12: =IFERROR(__xludf.DUMMYFUNCTION("""COMPUTED_VALUE"""),178.0) -> 178 | AG12: =IFERROR(__xludf.DUMMYFUNCTION("""COMPUTED_VALUE"""),89.0) -> 89 | AH12: =IFERROR(__xludf.DUMMYFUNCTION("""COMPUTED_VALUE"""),89.0) -> 89
A13: =IFERROR(__xludf.DUMMYFUNCTION("""COMPUTED_VALUE"""),"Y") -> Y | B13: =IFERROR(__xludf.DUMMYFUNCTION("""COMPUTED_VALUE"""),"2") -> 2 | C13: =IFERROR(__xludf.DUMMYFUNCTION("""COMPUTED_VALUE"""),"109-114") -> 109-114 | D13: =IFERROR(__xludf.DUMMYFUNCTION("""COMPUTED_VALUE"""),45577.0) -> 45577 | E13: =IFERROR(__xludf.DUMMYFUNCTION("""COMPUTED_VALUE"""),45584.0) -> 45584 | F13: =IFERROR(__xludf.DUMMYFUNCTION("""COMPUTED_VALUE"""),45605.0) -> 45605 | G13: =IFERROR(__xludf.DUMMYFUNCTION("""COMPUTED_VALUE"""),"D36-1L") -> D36-1L | L13: =IFERROR(__xludf.DUMMYFUNCTION("""COMPUTED_VALUE"""),2.0) -> 2 | M13: =IFERROR(__xludf.DUMMYFUNCTION("""COMPUTED_VALUE"""),178.0) -> 178 | N13: =IFERROR(__xludf.DUMMYFUNCTION("""COMPUTED_VALUE"""),89.0) -> 89 | O13: =IFERROR(__xludf.DUMMYFUNCTION("""COMPUTED_VALUE"""),89.0) -> 89 | T13: =IFERROR(__xludf.DUMMYFUNCTION("""COMPUTED_VALUE"""),"Y") -> Y | U13: =IFERROR(__xludf.DUMMYFUNCTION("""COMPUTED_VALUE"""),"2") -> 2 | V13: =IFERROR(__xludf.DUMMYFUNCTION("""COMPUTED_VALUE"""),"109-114") -> 109-114 | W13: =IFERROR(__xludf.DUMMYFUNCTION("""COMPUTED_VALUE"""),45577.0) -> 45577 | X13: =IFERROR(__xludf.DUMMYFUNCTION("""COMPUTED_VALUE"""),45584.0) -> 45584 | Y13: =IFERROR(__xludf.DUMMYFUNCTION("""COMPUTED_VALUE"""),45605.0) -> 45605 | Z13: =IFERROR(__xludf.DUMMYFUNCTION("""COMPUTED_VALUE"""),"D36-2L") -> D36-2L | AE13: =IFERROR(__xludf.DUMMYFUNCTION("""COMPUTED_VALUE"""),2.0) -> 2 | AF13: =IFERROR(__xludf.DUMMYFUNCTION("""COMPUTED_VALUE"""),24.0) -> 24 | AG13: =IFERROR(__xludf.DUMMYFUNCTION("""COMPUTED_VALUE"""),12.0) -> 12 | AH13: =IFERROR(__xludf.DUMMYFUNCTION("""COMPUTED_VALUE"""),12.0) -> 12
A14: =IFERROR(__xludf.DUMMYFUNCTION("""COMPUTED_VALUE"""),"Y") -> Y | B14: =IFERROR(__xludf.DUMMYFUNCTION("""COMPUTED_VALUE"""),"2") -> 2 | C14: =IFERROR(__xludf.DUMMYFUNCTION("""COMPUTED_VALUE"""),"109-114") -> 109-114 | D14: =IFERROR(__xludf.DUMMYFUNCTION("""COMPUTED_VALUE"""),45577.0) -> 45577 | E14: =IFERROR(__xludf.DUMMYFUNCTION("""COMPUTED_VALUE"""),45584.0) -> 45584 | F14: =IFERROR(__xludf.DUMMYFUNCTION("""COMPUTED_VALUE"""),45605.0) -> 45605 | G14: =IFERROR(__xludf.DUMMYFUNCTION("""COMPUTED_VALUE"""),"D36-2L") -> D36-2L | L14: =IFERROR(__xludf.DUMMYFUNCTION("""COMPUTED_VALUE"""),2.0) -> 2 | M14: =IFERROR(__xludf.DUMMYFUNCTION("""COMPUTED_VALUE"""),24.0) -> 24 | N14: =IFERROR(__xludf.DUMMYFUNCTION("""COMPUTED_VALUE"""),12.0) -> 12 | O14: =IFERROR(__xludf.DUMMYFUNCTION("""COMPUTED_VALUE"""),12.0) -> 12 | T14: =IFERROR(__xludf.DUMMYFUNCTION("""COMPUTED_VALUE"""),"Y") -> Y | U14: =IFERROR(__xludf.DUMMYFUNCTION("""COMPUTED_VALUE"""),"2") -> 2 | V14: =IFERROR(__xludf.DUMMYFUNCTION("""COMPUTED_VALUE"""),"115-120") -> 115-120 | W14: =IFERROR(__xludf.DUMMYFUNCTION("""COMPUTED_VALUE"""),45578.0) -> 45578 | X14: =IFERROR(__xludf.DUMMYFUNCTION("""COMPUTED_VALUE"""),45585.0) -> 45585 | Y14: =IFERROR(__xludf.DUMMYFUNCTION("""COMPUTED_VALUE"""),45606.0) -> 45606 | Z14: =IFERROR(__xludf.DUMMYFUNCTION("""COMPUTED_VALUE"""),"D36-2L") -> D36-2L | AA14: =IFERROR(__xludf.DUMMYFUNCTION("""COMPUTED_VALUE"""),163.0) -> 163 | AB14: =IFERROR(__xludf.DUMMYFUNCTION("""COMPUTED_VALUE"""),347.0) -> 347 | AC14: =IFERROR(__xludf.DUMMYFUNCTION("""COMPUTED_VALUE"""),93.0) -> 93 | AD14: =IFERROR(__xludf.DUMMYFUNCTION("""COMPUTED_VALUE"""),93.0) -> 93
A15: =IFERROR(__xludf.DUMMYFUNCTION("""COMPUTED_VALUE"""),"Y") -> Y | B15: =IFERROR(__xludf.DUMMYFUNCTION("""COMPUTED_VALUE"""),"2") -> 2 | C15: =IFERROR(__xludf.DUMMYFUNCTION("""COMPUTED_VALUE"""),"115-120") -> 115-120 | D15: =IFERROR(__xludf.DUMMYFUNCTION("""COMPUTED_VALUE"""),45578.0) -> 45578 | E15: =IFERROR(__xludf.DUMMYFUNCTION("""COMPUTED_VALUE"""),45585.0) -> 45585 | F15: =IFERROR(__xludf.DUMMYFUNCTION("""COMPUTED_VALUE"""),45606.0) -> 45606 | G15: =IFERROR(__xludf.DUMMYFUNCTION("""COMPUTED_VALUE"""),"D36-2L") -> D36-2L | H15: =IFERROR(__xludf.DUMMYFUNCTION("""COMPUTED_VALUE"""),163.0) -> 163 | I15: =IFERROR(__xludf.DUMMYFUNCTION("""COMPUTED_VALUE"""),347.0) -> 347 | J15: =IFERROR(__xludf.DUMMYFUNCTION("""COMPUTED_VALUE"""),93.0) -> 93 | K15: =IFERROR(__xludf.DUMMYFUNCTION("""COMPUTED_VALUE"""),93.0) -> 93 | T15: =IFERROR(__xludf.DUMMYFUNCTION("""COMPUTED_VALUE"""),"Y") -> Y | U15: =IFERROR(__xludf.DUMMYFUNCTION("""COMPUTED_VALUE"""),"2") -> 2 | V15: =IFERROR(__xludf.DUMMYFUNCTION("""COMPUTED_VALUE"""),"127-132") -> 127-132 | W15: =IFERROR(__xludf.DUMMYFUNCTION("""COMPUTED_VALUE"""),45579.0) -> 45579 | X15: =IFERROR(__xludf.DUMMYFUNCTION("""COMPUTED_VALUE"""),45586.0) -> 45586 | Y15: =IFERROR(__xludf.DUMMYFUNCTION("""COMPUTED_VALUE"""),45607.0) -> 45607 | Z15: =IFERROR(__xludf.DUMMYFUNCTION("""COMPUTED_VALUE"""),"D34-1L") -> D34-1L | AA15: =IFERROR(__xludf.DUMMYFUNCTION("""COMPUTED_VALUE"""),31.0) -> 31 | AB15: =IFERROR(__xludf.DUMMYFUNCTION("""COMPUTED_VALUE"""),183.0) -> 183 | AC15: =IFERROR(__xludf.DUMMYFUNCTION("""COMPUTED_VALUE"""),77.0) -> 77 | AD15: =IFERROR(__xludf.DUMMYFUNCTION("""COMPUTED_VALUE"""),77.0) -> 77
A16: =IFERROR(__xludf.DUMMYFUNCTION("""COMPUTED_VALUE"""),"Y") -> Y | B16: =IFERROR(__xludf.DUMMYFUNCTION("""COMPUTED_VALUE"""),"2") -> 2 | C16: =IFERROR(__xludf.DUMMYFUNCTION("""COMPUTED_VALUE"""),"127-132") -> 127-132 | D16: =IFERROR(__xludf.DUMMYFUNCTION("""COMPUTED_VALUE"""),45579.0) -> 45579 | E16: =IFERROR(__xludf.DUMMYFUNCTION("""COMPUTED_VALUE"""),45586.0) -> 45586 | F16: =IFERROR(__xludf.DUMMYFUNCTION("""COMPUTED_VALUE"""),45607.0) -> 45607 | G16: =IFERROR(__xludf.DUMMYFUNCTION("""COMPUTED_VALUE"""),"D34-1L") -> D34-1L | H16: =IFERROR(__xludf.DUMMYFUNCTION("""COMPUTED_VALUE"""),31.0) -> 31 | I16: =IFERROR(__xludf.DUMMYFUNCTION("""COMPUTED_VALUE"""),183.0) -> 183 | J16: =IFERROR(__xludf.DUMMYFUNCTION("""COMPUTED_VALUE"""),77.0) -> 77 | K16: =IFERROR(__xludf.DUMMYFUNCTION("""COMPUTED_VALUE"""),77.0) -> 77 | T16: =IFERROR(__xludf.DUMMYFUNCTION("""COMPUTED_VALUE"""),"Y") -> Y | U16: =IFERROR(__xludf.DUMMYFUNCTION("""COMPUTED_VALUE"""),"2") -> 2 | V16: =IFERROR(__xludf.DUMMYFUNCTION("""COMPUTED_VALUE"""),"133-138") -> 133-138 | W16: =IFERROR(__xludf.DUMMYFUNCTION("""COMPUTED_VALUE"""),45579.0) -> 45579 | X16: =IFERROR(__xludf.DUMMYFUNCTION("""COMPUTED_VALUE"""),45586.0) -> 45586 | Y16: =IFERROR(__xludf.DUMMYFUNCTION("""COMPUTED_VALUE"""),45607.0) -> 45607 | Z16: =IFERROR(__xludf.DUMMYFUNCTION("""COMPUTED_VALUE"""),"D36-2L") -> D36-2L | AE16: =IFERROR(__xludf.DUMMYFUNCTION("""COMPUTED_VALUE"""),26.0) -> 26 | AF16: =IFERROR(__xludf.DUMMYFUNCTION("""COMPUTED_VALUE"""),220.0) -> 220 | AG16: =IFERROR(__xludf.DUMMYFUNCTION("""COMPUTED_VALUE"""),98.0) -> 98 | AH16: =IFERROR(__xludf.DUMMYFUNCTION("""COMPUTED_VALUE"""),98.0) -> 98
A17: =IFERROR(__xludf.DUMMYFUNCTION("""COMPUTED_VALUE"""),"Y") -> Y | B17: =IFERROR(__xludf.DUMMYFUNCTION("""COMPUTED_VALUE"""),"2") -> 2 | C17: =IFERROR(__xludf.DUMMYFUNCTION("""COMPUTED_VALUE"""),"133-138") -> 133-138 | D17: =IFERROR(__xludf.DUMMYFUNCTION("""COMPUTED_VALUE"""),45579.0) -> 45579 | E17: =IFERROR(__xludf.DUMMYFUNCTION("""COMPUTED_VALUE"""),45586.0) -> 45586 | F17: =IFERROR(__xludf.DUMMYFUNCTION("""COMPUTED_VALUE"""),45607.0) -> 45607 | G17: =IFERROR(__xludf.DUMMYFUNCTION("""COMPUTED_VALUE"""),"D36-2L") -> D36-2L | L17: =IFERROR(__xludf.DUMMYFUNCTION("""COMPUTED_VALUE"""),26.0) -> 26 | M17: =IFERROR(__xludf.DUMMYFUNCTION("""COMPUTED_VALUE"""),220.0) -> 220 | N17: =IFERROR(__xludf.DUMMYFUNCTION("""COMPUTED_VALUE"""),98.0) -> 98 | O17: =IFERROR(__xludf.DUMMYFUNCTION("""COMPUTED_VALUE"""),98.0) -> 98 | T17: =IFERROR(__xludf.DUMMYFUNCTION("""COMPUTED_VALUE"""),"Y") -> Y | U17: =IFERROR(__xludf.DUMMYFUNCTION("""COMPUTED_VALUE"""),"2") -> 2 | V17: =IFERROR(__xludf.DUMMYFUNCTION("""COMPUTED_VALUE"""),"151-156") -> 151-156 | W17: =IFERROR(__xludf.DUMMYFUNCTION("""COMPUTED_VALUE"""),45580.0) -> 45580 | X17: =IFERROR(__xludf.DUMMYFUNCTION("""COMPUTED_VALUE"""),45587.0) -> 45587 | Y17: =IFERROR(__xludf.DUMMYFUNCTION("""COMPUTED_VALUE"""),45608.0) -> 45608 | Z17: =IFERROR(__xludf.DUMMYFUNCTION("""COMPUTED_VALUE"""),"D34-1L") -> D34-1L | AA17: =IFERROR(__xludf.DUMMYFUNCTION("""COMPUTED_VALUE"""),185.0) -> 185 | AB17: =IFERROR(__xludf.DUMMYFUNCTION("""COMPUTED_VALUE"""),299.0) -> 299 | AC17: =IFERROR(__xludf.DUMMYFUNCTION("""COMPUTED_VALUE"""),58.0) -> 58 | AD17: =IFERROR(__xludf.DUMMYFUNCTION("""COMPUTED_VALUE"""),58.0) -> 58
A18: =IFERROR(__xludf.DUMMYFUNCTION("""COMPUTED_VALUE"""),"Y") -> Y | B18: =IFERROR(__xludf.DUMMYFUNCTION("""COMPUTED_VALUE"""),"2") -> 2 | C18: =IFERROR(__xludf.DUMMYFUNCTION("""COMPUTED_VALUE"""),"151-156") -> 151-156 | D18: =IFERROR(__xludf.DUMMYFUNCTION("""COMPUTED_VALUE"""),45580.0) -> 45580 | E18: =IFERROR(__xludf.DUMMYFUNCTION("""COMPUTED_VALUE"""),45587.0) -> 45587 | F18: =IFERROR(__xludf.DUMMYFUNCTION("""COMPUTED_VALUE"""),45608.0) -> 45608 | G18: =IFERROR(__xludf.DUMMYFUNCTION("""COMPUTED_VALUE"""),"D34-1L") -> D34-1L | H18: =IFERROR(__xludf.DUMMYFUNCTION("""COMPUTED_VALUE"""),185.0) -> 185 | I18: =IFERROR(__xludf.DUMMYFUNCTION("""COMPUTED_VALUE"""),299.0) -> 299 | J18: =IFERROR(__xludf.DUMMYFUNCTION("""COMPUTED_VALUE"""),58.0) -> 58 | K18: =IFERROR(__xludf.DUMMYFUNCTION("""COMPUTED_VALUE"""),58.0) -> 58 | T18: =IFERROR(__xludf.DUMMYFUNCTION("""COMPUTED_VALUE"""),"Y") -> Y | U18: =IFERROR(__xludf.DUMMYFUNCTION("""COMPUTED_VALUE"""),"2") -> 2 | V18: =IFERROR(__xludf.DUMMYFUNCTION("""COMPUTED_VALUE"""),"151-156") -> 151-156 | W18: =IFERROR(__xludf.DUMMYFUNCTION("""COMPUTED_VALUE"""),45580.0) -> 45580 | X18: =IFERROR(__xludf.DUMMYFUNCTION("""COMPUTED_VALUE"""),45587.0) -> 45587 | Y18: =IFERROR(__xludf.DUMMYFUNCTION("""COMPUTED_VALUE"""),45608.0) -> 45608 | Z18: =IFERROR(__xludf.DUMMYFUNCTION("""COMPUTED_VALUE"""),"D34-1L") -> D34-1L | AE18: =IFERROR(__xludf.DUMMYFUNCTION("""COMPUTED_VALUE"""),4.0) -> 4 | AF18: =IFERROR(__xludf.DUMMYFUNCTION("""COMPUTED_VALUE"""),8.0) -> 8 | AG18: =IFERROR(__xludf.DUMMYFUNCTION("""COMPUTED_VALUE"""),3.0) -> 3 | AH18: =IFERROR(__xludf.DUMMYFUNCTION("""COMPUTED_VALUE"""),3.0) -> 3
A19: =IFERROR(__xludf.DUMMYFUNCTION("""COMPUTED_VALUE"""),"Y") -> Y | B19: =IFERROR(__xludf.DUMMYFUNCTION("""COMPUTED_VALUE"""),"2") -> 2 | C19: =IFERROR(__xludf.DUMMYFUNCTION("""COMPUTED_VALUE"""),"151-156") -> 151-156 | D19: =IFERROR(__xludf.DUMMYFUNCTION("""COMPUTED_VALUE"""),45580.0) -> 45580 | E19: =IFERROR(__xludf.DUMMYFUNCTION("""COMPUTED_VALUE"""),45587.0) -> 45587 | F19: =IFERROR(__xludf.DUMMYFUNCTION("""COMPUTED_VALUE"""),45608.0) -> 45608 | G19: =IFERROR(__xludf.DUMMYFUNCTION("""COMPUTED_VALUE"""),"D34-1L") -> D34-1L | L19: =IFERROR(__xludf.DUMMYFUNCTION("""COMPUTED_VALUE"""),4.0) -> 4 | M19: =IFERROR(__xludf.DUMMYFUNCTION("""COMPUTED_VALUE"""),8.0) -> 8 | N19: =IFERROR(__xludf.DUMMYFUNCTION("""COMPUTED_VALUE"""),3.0) -> 3 | O19: =IFERROR(__xludf.DUMMYFUNCTION("""COMPUTED_VALUE"""),3.0) -> 3 | T19: =IFERROR(__xludf.DUMMYFUNCTION("""COMPUTED_VALUE"""),"Y") -> Y | U19: =IFERROR(__xludf.DUMMYFUNCTION("""COMPUTED_VALUE"""),"2") -> 2 | V19: =IFERROR(__xludf.DUMMYFUNCTION("""COMPUTED_VALUE"""),"157-162") -> 157-162 | W19: =IFERROR(__xludf.DUMMYFUNCTION("""COMPUTED_VALUE"""),45580.0) -> 45580 | X19: =IFERROR(__xludf.DUMMYFUNCTION("""COMPUTED_VALUE"""),45587.0) -> 45587 | Y19: =IFERROR(__xludf.DUMMYFUNCTION("""COMPUTED_VALUE"""),45608.0) -> 45608 | Z19: =IFERROR(__xludf.DUMMYFUNCTION("""COMPUTED_VALUE"""),"D36-2L") -> D36-2L | AE19: =IFERROR(__xludf.DUMMYFUNCTION("""COMPUTED_VALUE"""),220.0) -> 220 | AF19: =IFERROR(__xludf.DUMMYFUNCTION("""COMPUTED_VALUE"""),248.0) -> 248 | AG19: =IFERROR(__xludf.DUMMYFUNCTION("""COMPUTED_VALUE"""),15.0) -> 15 | AH19: =IFERROR(__xludf.DUMMYFUNCTION("""COMPUTED_VALUE"""),15.0) -> 15
A20: =IFERROR(__xludf.DUMMYFUNCTION("""COMPUTED_VALUE"""),"Y") -> Y | B20: =IFERROR(__xludf.DUMMYFUNCTION("""COMPUTED_VALUE"""),"2") -> 2 | C20: =IFERROR(__xludf.DUMMYFUNCTION("""COMPUTED_VALUE"""),"157-162") -> 157-162 | D20: =IFERROR(__xludf.DUMMYFUNCTION("""COMPUTED_VALUE"""),45580.0) -> 45580 | E20: =IFERROR(__xludf.DUMMYFUNCTION("""COMPUTED_VALUE"""),45587.0) -> 45587 | F20: =IFERROR(__xludf.DUMMYFUNCTION("""COMPUTED_VALUE"""),45608.0) -> 45608 | G20: =IFERROR(__xludf.DUMMYFUNCTION("""COMPUTED_VALUE"""),"D36-2L") -> D36-2L | L20: =IFERROR(__xludf.DUMMYFUNCTION("""COMPUTED_VALUE"""),220.0) -> 220 | M20: =IFERROR(__xludf.DUMMYFUNCTION("""COMPUTED_VALUE"""),248.0) -> 248 | N20: =IFERROR(__xludf.DUMMYFUNCTION("""COMPUTED_VALUE"""),15.0) -> 15 | O20: =IFERROR(__xludf.DUMMYFUNCTION("""COMPUTED_VALUE"""),15.0) -> 15 | T20: =IFERROR(__xludf.DUMMYFUNCTION("""COMPUTED_VALUE"""),"Y") -> Y | U20: =IFERROR(__xludf.DUMMYFUNCTION("""COMPUTED_VALUE"""),"2") -> 2 | V20: =IFERROR(__xludf.DUMMYFUNCTION("""COMPUTED_VALUE"""),"169-174") -> 169-174 | W20: =IFERROR(__xludf.DUMMYFUNCTION("""COMPUTED_VALUE"""),45581.0) -> 45581 | X20: =IFERROR(__xludf.DUMMYFUNCTION("""COMPUTED_VALUE"""),45588.0) -> 45588 | Y20: =IFERROR(__xludf.DUMMYFUNCTION("""COMPUTED_VALUE"""),45609.0) -> 45609 | Z20: =IFERROR(__xludf.DUMMYFUNCTION("""COMPUTED_VALUE"""),"D34-1L") -> D34-1L | AE20: =IFERROR(__xludf.DUMMYFUNCTION("""COMPUTED_VALUE"""),10.0) -> 10 | AF20: =IFERROR(__xludf.DUMMYFUNCTION("""COMPUTED_VALUE"""),180.0) -> 180 | AG20: =IFERROR(__xludf.DUMMYFUNCTION("""COMPUTED_VALUE"""),86.0) -> 86 | AH20: =IFERROR(__xludf.DUMMYFUNCTION("""COMPUTED_VALUE"""),86.0) -> 86
A21: =IFERROR(__xludf.DUMMYFUNCTION("""COMPUTED_VALUE"""),"Y") -> Y | B21: =IFERROR(__xludf.DUMMYFUNCTION("""COMPUTED_VALUE"""),"2") -> 2 | C21: =IFERROR(__xludf.DUMMYFUNCTION("""COMPUTED_VALUE"""),"169-174") -> 169-174 | D21: =IFERROR(__xludf.DUMMYFUNCTION("""COMPUTED_VALUE"""),45581.0) -> 45581 | E21: =IFERROR(__xludf.DUMMYFUNCTION("""COMPUTED_VALUE"""),45588.0) -> 45588 | F21: =IFERROR(__xludf.DUMMYFUNCTION("""COMPUTED_VALUE"""),45609.0) -> 45609 | G21: =IFERROR(__xludf.DUMMYFUNCTION("""COMPUTED_VALUE"""),"D34-1L") -> D34-1L | L21: =IFERROR(__xludf.DUMMYFUNCTION("""COMPUTED_VALUE"""),10.0) -> 10 | M21: =IFERROR(__xludf.DUMMYFUNCTION("""COMPUTED_VALUE"""),180.0) -> 180 | N21: =IFERROR(__xludf.DUMMYFUNCTION("""COMPUTED_VALUE"""),86.0) -> 86 | O21: =IFERROR(__xludf.DUMMYFUNCTION("""COMPUTED_VALUE"""),86.0) -> 86 | T21: =IFERROR(__xludf.DUMMYFUNCTION("""COMPUTED_VALUE"""),"Y") -> Y | U21: =IFERROR(__xludf.DUMMYFUNCTION("""COMPUTED_VALUE"""),"2") -> 2 | V21: =IFERROR(__xludf.DUMMYFUNCTION("""COMPUTED_VALUE"""),"187-192") -> 187-192 | W21: =IFERROR(__xludf.DUMMYFUNCTION("""COMPUTED_VALUE"""),45582.0) -> 45582 | X21: =IFERROR(__xludf.DUMMYFUNCTION("""COMPUTED_VALUE"""),45589.0) -> 45589 | Y21: =IFERROR(__xludf.DUMMYFUNCTION("""COMPUTED_VALUE"""),45610.0) -> 45610 | Z21: =IFERROR(__xludf.DUMMYFUNCTION("""COMPUTED_VALUE"""),"D34-2L") -> D34-2L | AA21: =IFERROR(__xludf.DUMMYFUNCTION("""COMPUTED_VALUE"""),1.0) -> 1 | AB21: =IFERROR(__xludf.DUMMYFUNCTION("""COMPUTED_VALUE"""),201.0) -> 201 | AC21: =IFERROR(__xludf.DUMMYFUNCTION("""COMPUTED_VALUE"""),101.0) -> 101 | AD21: =IFERROR(__xludf.DUMMYFUNCTION("""COMPUTED_VALUE"""),101.0) -> 101
A22: =IFERROR(__xludf.DUMMYFUNCTION("""COMPUTED_VALUE"""),"Y") -> Y | B22: =IFERROR(__xludf.DUMMYFUNCTION("""COMPUTED_VALUE"""),"2") -> 2 | C22: =IFERROR(__xludf.DUMMYFUNCTION("""COMPUTED_VALUE"""),"187-192") -> 187-192 | D22: =IFERROR(__xludf.DUMMYFUNCTION("""COMPUTED_VALUE"""),45582.0) -> 45582 | E22: =IFERROR(__xludf.DUMMYFUNCTION("""COMPUTED_VALUE"""),45589.0) -> 45589 | F22: =IFERROR(__xludf.DUMMYFUNCTION("""COMPUTED_VALUE"""),45610.0) -> 45610 | G22: =IFERROR(__xludf.DUMMYFUNCTION("""COMPUTED_VALUE"""),"D34-2L") -> D34-2L | H22: =IFERROR(__xludf.DUMMYFUNCTION("""COMPUTED_VALUE"""),1.0) -> 1 | I22: =IFERROR(__xludf.DUMMYFUNCTION("""COMPUTED_VALUE"""),201.0) -> 201 | J22: =IFERROR(__xludf.DUMMYFUNCTION("""COMPUTED_VALUE"""),101.0) -> 101 | K22: =IFERROR(__xludf.DUMMYFUNCTION("""COMPUTED_VALUE"""),101.0) -> 101 | T22: =IFERROR(__xludf.DUMMYFUNCTION("""COMPUTED_VALUE"""),"Y") -> Y | U22: =IFERROR(__xludf.DUMMYFUNCTION("""COMPUTED_VALUE"""),"2") -> 2 | V22: =IFERROR(__xludf.DUMMYFUNCTION("""COMPUTED_VALUE"""),"205-210") -> 205-210 | W22: =IFERROR(__xludf.DUMMYFUNCTION("""COMPUTED_VALUE"""),45584.0) -> 45584 | X22: =IFERROR(__xludf.DUMMYFUNCTION("""COMPUTED_VALUE"""),45591.0) -> 45591 | Y22: =IFERROR(__xludf.DUMMYFUNCTION("""COMPUTED_VALUE"""),45612.0) -> 45612 | Z22: =IFERROR(__xludf.DUMMYFUNCTION("""COMPUTED_VALUE"""),"D34-2L") -> D34-2L | AE22: =IFERROR(__xludf.DUMMYFUNCTION("""COMPUTED_VALUE"""),2.0) -> 2 | AF22: =IFERROR(__xludf.DUMMYFUNCTION("""COMPUTED_VALUE"""),104.0) -> 104 | AG22: =IFERROR(__xludf.DUMMYFUNCTION("""COMPUTED_VALUE"""),52.0) -> 52 | AH22: =IFERROR(__xludf.DUMMYFUNCTION("""COMPUTED_VALUE"""),52.0) -> 52
A23: =IFERROR(__xludf.DUMMYFUNCTION("""COMPUTED_VALUE"""),"Y") -> Y | B23: =IFERROR(__xludf.DUMMYFUNCTION("""COMPUTED_VALUE"""),"2") -> 2 | C23: =IFERROR(__xludf.DUMMYFUNCTION("""COMPUTED_VALUE"""),"205-210") -> 205-210 | D23: =IFERROR(__xludf.DUMMYFUNCTION("""COMPUTED_VALUE"""),45584.0) -> 45584 | E23: =IFERROR(__xludf.DUMMYFUNCTION("""COMPUTED_VALUE"""),45591.0) -> 45591 | F23: =IFERROR(__xludf.DUMMYFUNCTION("""COMPUTED_VALUE"""),45612.0) -> 45612 | G23: =IFERROR(__xludf.DUMMYFUNCTION("""COMPUTED_VALUE"""),"D34-2L") -> D34-2L | L23: =IFERROR(__xludf.DUMMYFUNCTION("""COMPUTED_VALUE"""),2.0) -> 2 | M23: =IFERROR(__xludf.DUMMYFUNCTION("""COMPUTED_VALUE"""),104.0) -> 104 | N23: =IFERROR(__xludf.DUMMYFUNCTION("""COMPUTED_VALUE"""),52.0) -> 52 | O23: =IFERROR(__xludf.DUMMYFUNCTION("""COMPUTED_VALUE"""),52.0) -> 52 | T23: =IFERROR(__xludf.DUMMYFUNCTION("""COMPUTED_VALUE"""),"Y") -> Y | U23: =IFERROR(__xludf.DUMMYFUNCTION("""COMPUTED_VALUE"""),"2") -> 2 | V23: =IFERROR(__xludf.DUMMYFUNCTION("""COMPUTED_VALUE"""),"205-210") -> 205-210 | W23: =IFERROR(__xludf.DUMMYFUNCTION("""COMPUTED_VALUE"""),45584.0) -> 45584 | X23: =IFERROR(__xludf.DUMMYFUNCTION("""COMPUTED_VALUE"""),45591.0) -> 45591 | Y23: =IFERROR(__xludf.DUMMYFUNCTION("""COMPUTED_VALUE"""),45612.0) -> 45612 | Z23: =IFERROR(__xludf.DUMMYFUNCTION("""COMPUTED_VALUE"""),"D34-2L") -> D34-2L | AA23: =IFERROR(__xludf.DUMMYFUNCTION("""COMPUTED_VALUE"""),203.0) -> 203 | AB23: =IFERROR(__xludf.DUMMYFUNCTION("""COMPUTED_VALUE"""),255.0) -> 255 | AC23: =IFERROR(__xludf.DUMMYFUNCTION("""COMPUTED_VALUE"""),27.0) -> 27 | AD23: =IFERROR(__xludf.DUMMYFUNCTION("""COMPUTED_VALUE"""),27.0) -> 27
A24: =IFERROR(__xludf.DUMMYFUNCTION("""COMPUTED_VALUE"""),"Y") -> Y | B24: =IFERROR(__xludf.DUMMYFUNCTION("""COMPUTED_VALUE"""),"2") -> 2 | C24: =IFERROR(__xludf.DUMMYFUNCTION("""COMPUTED_VALUE"""),"205-210") -> 205-210 | D24: =IFERROR(__xludf.DUMMYFUNCTION("""COMPUTED_VALUE"""),45584.0) -> 45584 | E24: =IFERROR(__xludf.DUMMYFUNCTION("""COMPUTED_VALUE"""),45591.0) -> 45591 | F24: =IFERROR(__xludf.DUMMYFUNCTION("""COMPUTED_VALUE"""),45612.0) -> 45612 | G24: =IFERROR(__xludf.DUMMYFUNCTION("""COMPUTED_VALUE"""),"D34-2L") -> D34-2L | H24: =IFERROR(__xludf.DUMMYFUNCTION("""COMPUTED_VALUE"""),203.0) -> 203 | I24: =IFERROR(__xludf.DUMMYFUNCTION("""COMPUTED_VALUE"""),255.0) -> 255 | J24: =IFERROR(__xludf.DUMMYFUNCTION("""COMPUTED_VALUE"""),27.0) -> 27 | K24: =IFERROR(__xludf.DUMMYFUNCTION("""COMPUTED_VALUE"""),27.0) -> 27 | T24: =IFERROR(__xludf.DUMMYFUNCTION("""COMPUTED_VALUE"""),"Y") -> Y | U24: =IFERROR(__xludf.DUMMYFUNCTION("""COMPUTED_VALUE"""),"2") -> 2 | V24: =IFERROR(__xludf.DUMMYFUNCTION("""COMPUTED_VALUE"""),"217-222") -> 217-222 | W24: =IFERROR(__xludf.DUMMYFUNCTION("""COMPUTED_VALUE"""),45585.0) -> 45585 | X24: =IFERROR(__xludf.DUMMYFUNCTION("""COMPUTED_VALUE"""),45592.0) -> 45592 | Y24: =IFERROR(__xludf.DUMMYFUNCTION("""COMPUTED_VALUE"""),45613.0) -> 45613 | Z24: =IFERROR(__xludf.DUMMYFUNCTION("""COMPUTED_VALUE"""),"D34-2L") -> D34-2L | AA24: =IFERROR(__xludf.DUMMYFUNCTION("""COMPUTED_VALUE"""),257.0) -> 257 | AB24: =IFERROR(__xludf.DUMMYFUNCTION("""COMPUTED_VALUE"""),299.0) -> 299 | AC24: =IFERROR(__xludf.DUMMYFUNCTION("""COMPUTED_VALUE"""),22.0) -> 22 | AD24: =IFERROR(__xludf.DUMMYFUNCTION("""COMPUTED_VALUE"""),22.0) -> 22
A25: =IFERROR(__xludf.DUMMYFUNCTION("""COMPUTED_VALUE"""),"Y") -> Y | B25: =IFERROR(__xludf.DUMMYFUNCTION("""COMPUTED_VALUE"""),"2") -> 2 | C25: =IFERROR(__xludf.DUMMYFUNCTION("""COMPUTED_VALUE"""),"217-222") -> 217-222 | D25: =IFERROR(__xludf.DUMMYFUNCTION("""COMPUTED_VALUE"""),45585.0) -> 45585 | E25: =IFERROR(__xludf.DUMMYFUNCTION("""COMPUTED_VALUE"""),45592.0) -> 45592 | F25: =IFERROR(__xludf.DUMMYFUNCTION("""COMPUTED_VALUE"""),45613.0) -> 45613 | G25: =IFERROR(__xludf.DUMMYFUNCTION("""COMPUTED_VALUE"""),"D34-2L") -> D34-2L | H25: =IFERROR(__xludf.DUMMYFUNCTION("""COMPUTED_VALUE"""),257.0) -> 257 | I25: =IFERROR(__xludf.DUMMYFUNCTION("""COMPUTED_VALUE"""),299.0) -> 299 | J25: =IFERROR(__xludf.DUMMYFUNCTION("""COMPUTED_VALUE"""),22.0) -> 22 | K25: =IFERROR(__xludf.DUMMYFUNCTION("""COMPUTED_VALUE"""),22.0) -> 22 | T25: =IFERROR(__xludf.DUMMYFUNCTION("""COMPUTED_VALUE"""),"Y") -> Y | U25: =IFERROR(__xludf.DUMMYFUNCTION("""COMPUTED_VALUE"""),"2") -> 2 | V25: =IFERROR(__xludf.DUMMYFUNCTION("""COMPUTED_VALUE"""),"217-222") -> 217-222 | W25: =IFERROR(__xludf.DUMMYFUNCTION("""COMPUTED_VALUE"""),45585.0) -> 45585 | X25: =IFERROR(__xludf.DUMMYFUNCTION("""COMPUTED_VALUE"""),45592.0) -> 45592 | Y25: =IFERROR(__xludf.DUMMYFUNCTION("""COMPUTED_VALUE"""),45613.0) -> 45613 | Z25: =IFERROR(__xludf.DUMMYFUNCTION("""COMPUTED_VALUE"""),"D34-2L") -> D34-2L | AE25: =IFERROR(__xludf.DUMMYFUNCTION("""COMPUTED_VALUE"""),106.0) -> 106 | AF25: =IFERROR(__xludf.DUMMYFUNCTION("""COMPUTED_VALUE"""),254.0) -> 254 | AG25: =IFERROR(__xludf.DUMMYFUNCTION("""COMPUTED_VALUE"""),75.0) -> 75 | AH25: =IFERROR(__xludf.DUMMYFUNCTION("""COMPUTED_VALUE"""),75.0) -> 75
A26: =IFERROR(__xludf.DUMMYFUNCTION("""COMPUTED_VALUE"""),"Y") -> Y | B26: =IFERROR(__xludf.DUMMYFUNCTION("""COMPUTED_VALUE"""),"2") -> 2 | C26: =IFERROR(__xludf.DUMMYFUNCTION("""COMPUTED_VALUE"""),"217-222") -> 217-222 | D26: =IFERROR(__xludf.DUMMYFUNCTION("""COMPUTED_VALUE"""),45585.0) -> 45585 | E26: =IFERROR(__xludf.DUMMYFUNCTION("""COMPUTED_VALUE"""),45592.0) -> 45592 | F26: =IFERROR(__xludf.DUMMYFUNCTION("""COMPUTED_VALUE"""),45613.0) -> 45613 | G26: =IFERROR(__xludf.DUMMYFUNCTION("""COMPUTED_VALUE"""),"D34-2L") -> D34-2L | L26: =IFERROR(__xludf.DUMMYFUNCTION("""COMPUTED_VALUE"""),106.0) -> 106 | M26: =IFERROR(__xludf.DUMMYFUNCTION("""COMPUTED_VALUE"""),254.0) -> 254 | N26: =IFERROR(__xludf.DUMMYFUNCTION("""COMPUTED_VALUE"""),75.0) -> 75 | O26: =IFERROR(__xludf.DUMMYFUNCTION("""COMPUTED_VALUE"""),75.0) -> 75 | T26: =IFERROR(__xludf.DUMMYFUNCTION("""COMPUTED_VALUE"""),"Y") -> Y | U26: =IFERROR(__xludf.DUMMYFUNCTION("""COMPUTED_VALUE"""),"2") -> 2 | V26: =IFERROR(__xludf.DUMMYFUNCTION("""COMPUTED_VALUE"""),"229-234") -> 229-234 | W26: =IFERROR(__xludf.DUMMYFUNCTION("""COMPUTED_VALUE"""),45586.0) -> 45586 | X26: =IFERROR(__xludf.DUMMYFUNCTION("""COMPUTED_VALUE"""),45593.0) -> 45593 | Y26: =IFERROR(__xludf.DUMMYFUNCTION("""COMPUTED_VALUE"""),45614.0) -> 45614 | Z26: =IFERROR(__xludf.DUMMYFUNCTION("""COMPUTED_VALUE"""),"D34-2R") -> D34-2R | AA26: =IFERROR(__xludf.DUMMYFUNCTION("""COMPUTED_VALUE"""),1.0) -> 1 | AB26: =IFERROR(__xludf.DUMMYFUNCTION("""COMPUTED_VALUE"""),201.0) -> 201 | AC26: =IFERROR(__xludf.DUMMYFUNCTION("""COMPUTED_VALUE"""),101.0) -> 101 | AD26: =IFERROR(__xludf.DUMMYFUNCTION("""COMPUTED_VALUE"""),101.0) -> 101
A27: =IFERROR(__xludf.DUMMYFUNCTION("""COMPUTED_VALUE"""),"Y") -> Y | B27: =IFERROR(__xludf.DUMMYFUNCTION("""COMPUTED_VALUE"""),"2") -> 2 | C27: =IFERROR(__xludf.DUMMYFUNCTION("""COMPUTED_VALUE"""),"229-234") -> 229-234 | D27: =IFERROR(__xludf.DUMMYFUNCTION("""COMPUTED_VALUE"""),45586.0) -> 45586 | E27: =IFERROR(__xludf.DUMMYFUNCTION("""COMPUTED_VALUE"""),45593.0) -> 45593 | F27: =IFERROR(__xludf.DUMMYFUNCTION("""COMPUTED_VALUE"""),45614.0) -> 45614 | G27: =IFERROR(__xludf.DUMMYFUNCTION("""COMPUTED_VALUE"""),"D34-2R") -> D34-2R | H27: =IFERROR(__xludf.DUMMYFUNCTION("""COMPUTED_VALUE"""),1.0) -> 1 | I27: =IFERROR(__xludf.DUMMYFUNCTION("""COMPUTED_VALUE"""),201.0) -> 201 | J27: =IFERROR(__xludf.DUMMYFUNCTION("""COMPUTED_VALUE"""),101.0) -> 101 | K27: =IFERROR(__xludf.DUMMYFUNCTION("""COMPUTED_VALUE"""),101.0) -> 101 | T27: =IFERROR(__xludf.DUMMYFUNCTION("""COMPUTED_VALUE"""),"Y") -> Y | U27: =IFERROR(__xludf.DUMMYFUNCTION("""COMPUTED_VALUE"""),"2") -> 2 | V27: =IFERROR(__xludf.DUMMYFUNCTION("""COMPUTED_VALUE"""),"241-246") -> 241-246 | W27: =IFERROR(__xludf.DUMMYFUNCTION("""COMPUTED_VALUE"""),45587.0) -> 45587 | X27: =IFERROR(__xludf.DUMMYFUNCTION("""COMPUTED_VALUE"""),45594.0) -> 45594 | Y27: =IFERROR(__xludf.DUMMYFUNCTION("""COMPUTED_VALUE"""),45615.0) -> 45615 | Z27: =IFERROR(__xludf.DUMMYFUNCTION("""COMPUTED_VALUE"""),"D34-2R") -> D34-2R | AE27: =IFERROR(__xludf.DUMMYFUNCTION("""COMPUTED_VALUE"""),2.0) -> 2 | AF27: =IFERROR(__xludf.DUMMYFUNCTION("""COMPUTED_VALUE"""),160.0) -> 160 | AG27: =IFERROR(__xludf.DUMMYFUNCTION("""COMPUTED_VALUE"""),80.0) -> 80 | AH27: =IFERROR(__xludf.DUMMYFUNCTION("""COMPUTED_VALUE"""),80.0) -> 80
A28: =IFERROR(__xludf.DUMMYFUNCTION("""COMPUTED_VALUE"""),"Y") -> Y | B28: =IFERROR(__xludf.DUMMYFUNCTION("""COMPUTED_VALUE"""),"2") -> 2 | C28: =IFERROR(__xludf.DUMMYFUNCTION("""COMPUTED_VALUE"""),"241-246") -> 241-246 | D28: =IFERROR(__xludf.DUMMYFUNCTION("""COMPUTED_VALUE"""),45587.0) -> 45587 | E28: =IFERROR(__xludf.DUMMYFUNCTION("""COMPUTED_VALUE"""),45594.0) -> 45594 | F28: =IFERROR(__xludf.DUMMYFUNCTION("""COMPUTED_VALUE"""),45615.0) -> 45615 | G28: =IFERROR(__xludf.DUMMYFUNCTION("""COMPUTED_VALUE"""),"D34-2R") -> D34-2R | L28: =IFERROR(__xludf.DUMMYFUNCTION("""COMPUTED_VALUE"""),2.0) -> 2 | M28: =IFERROR(__xludf.DUMMYFUNCTION("""COMPUTED_VALUE"""),160.0) -> 160 | N28: =IFERROR(__xludf.DUMMYFUNCTION("""COMPUTED_VALUE"""),80.0) -> 80 | O28: =IFERROR(__xludf.DUMMYFUNCTION("""COMPUTED_VALUE"""),80.0) -> 80 | T28: =IFERROR(__xludf.DUMMYFUNCTION("""COMPUTED_VALUE"""),"Y") -> Y | U28: =IFERROR(__xludf.DUMMYFUNCTION("""COMPUTED_VALUE"""),"2") -> 2 | V28: =IFERROR(__xludf.DUMMYFUNCTION("""COMPUTED_VALUE"""),"241-246") -> 241-246 | W28: =IFERROR(__xludf.DUMMYFUNCTION("""COMPUTED_VALUE"""),45587.0) -> 45587 | X28: =IFERROR(__xludf.DUMMYFUNCTION("""COMPUTED_VALUE"""),45594.0) -> 45594 | Y28: =IFERROR(__xludf.DUMMYFUNCTION("""COMPUTED_VALUE"""),45615.0) -> 45615 | Z28: =IFERROR(__xludf.DUMMYFUNCTION("""COMPUTED_VALUE"""),"D34-2L") -> D34-2L | AE28: =IFERROR(__xludf.DUMMYFUNCTION("""COMPUTED_VALUE"""),256.0) -> 256 | AF28: =IFERROR(__xludf.DUMMYFUNCTION("""COMPUTED_VALUE"""),298.0) -> 298 | AG28: =IFERROR(__xludf.DUMMYFUNCTION("""COMPUTED_VALUE"""),22.0) -> 22 | AH28: =IFERROR(__xludf.DUMMYFUNCTION("""COMPUTED_VALUE"""),22.0) -> 22
A29: =IFERROR(__xludf.DUMMYFUNCTION("""COMPUTED_VALUE"""),"Y") -> Y | B29: =IFERROR(__xludf.DUMMYFUNCTION("""COMPUTED_VALUE"""),"2") -> 2 | C29: =IFERROR(__xludf.DUMMYFUNCTION("""COMPUTED_VALUE"""),"241-246") -> 241-246 | D29: =IFERROR(__xludf.DUMMYFUNCTION("""COMPUTED_VALUE"""),45587.0) -> 45587 | E29: =IFERROR(__xludf.DUMMYFUNCTION("""COMPUTED_VALUE"""),45594.0) -> 45594 | F29: =IFERROR(__xludf.DUMMYFUNCTION("""COMPUTED_VALUE"""),45615.0) -> 45615 | G29: =IFERROR(__xludf.DUMMYFUNCTION("""COMPUTED_VALUE"""),"D34-2L") -> D34-2L | L29: =IFERROR(__xludf.DUMMYFUNCTION("""COMPUTED_VALUE"""),256.0) -> 256 | M29: =IFERROR(__xludf.DUMMYFUNCTION("""COMPUTED_VALUE"""),298.0) -> 298 | N29: =IFERROR(__xludf.DUMMYFUNCTION("""COMPUTED_VALUE"""),22.0) -> 22 | O29: =IFERROR(__xludf.DUMMYFUNCTION("""COMPUTED_VALUE"""),22.0) -> 22 | T29: =IFERROR(__xludf.DUMMYFUNCTION("""COMPUTED_VALUE"""),"Y") -> Y | U29: =IFERROR(__xludf.DUMMYFUNCTION("""COMPUTED_VALUE"""),"2") -> 2 | V29: =IFERROR(__xludf.DUMMYFUNCTION("""COMPUTED_VALUE"""),"253-258") -> 253-258 | W29: =IFERROR(__xludf.DUMMYFUNCTION("""COMPUTED_VALUE"""),45588.0) -> 45588 | X29: =IFERROR(__xludf.DUMMYFUNCTION("""COMPUTED_VALUE"""),45595.0) -> 45595 | Y29: =IFERROR(__xludf.DUMMYFUNCTION("""COMPUTED_VALUE"""),45616.0) -> 45616 | Z29: =IFERROR(__xludf.DUMMYFUNCTION("""COMPUTED_VALUE"""),"D34-1L") -> D34-1L | AE29: =IFERROR(__xludf.DUMMYFUNCTION("""COMPUTED_VALUE"""),182.0) -> 182 | AF29: =IFERROR(__xludf.DUMMYFUNCTION("""COMPUTED_VALUE"""),266.0) -> 266 | AG29: =IFERROR(__xludf.DUMMYFUNCTION("""COMPUTED_VALUE"""),43.0) -> 43 | AH29: =IFERROR(__xludf.DUMMYFUNCTION("""COMPUTED_VALUE"""),43.0) -> 43
A30: =IFERROR(__xludf.DUMMYFUNCTION("""COMPUTED_VALUE"""),"Y") -> Y | B30: =IFERROR(__xludf.DUMMYFUNCTION("""COMPUTED_VALUE"""),"2") -> 2 | C30: =IFERROR(__xludf.DUMMYFUNCTION("""COMPUTED_VALUE"""),"253-258") -> 253-258 | D30: =IFERROR(__xludf.DUMMYFUNCTION("""COMPUTED_VALUE"""),45588.0) -> 45588 | E30: =IFERROR(__xludf.DUMMYFUNCTION("""COMPUTED_VALUE"""),45595.0) -> 45595 | F30: =IFERROR(__xludf.DUMMYFUNCTION("""COMPUTED_VALUE"""),45616.0) -> 45616 | G30: =IFERROR(__xludf.DUMMYFUNCTION("""COMPUTED_VALUE"""),"D34-1L") -> D34-1L | L30: =IFERROR(__xludf.DUMMYFUNCTION("""COMPUTED_VALUE"""),182.0) -> 182 | M30: =IFERROR(__xludf.DUMMYFUNCTION("""COMPUTED_VALUE"""),266.0) -> 266 | N30: =IFERROR(__xludf.DUMMYFUNCTION("""COMPUTED_VALUE"""),43.0) -> 43 | O30: =IFERROR(__xludf.DUMMYFUNCTION("""COMPUTED_VALUE"""),43.0) -> 43 | T30: =IFERROR(__xludf.DUMMYFUNCTION("""COMPUTED_VALUE"""),"Y") -> Y | U30: =IFERROR(__xludf.DUMMYFUNCTION("""COMPUTED_VALUE"""),"2") -> 2 | V30: =IFERROR(__xludf.DUMMYFUNCTION("""COMPUTED_VALUE"""),"253-258") -> 253-258 | W30: =IFERROR(__xludf.DUMMYFUNCTION("""COMPUTED_VALUE"""),45588.0) -> 45588 | X30: =IFERROR(__xludf.DUMMYFUNCTION("""COMPUTED_VALUE"""),45595.0) -> 45595 | Y30: =IFERROR(__xludf.DUMMYFUNCTION("""COMPUTED_VALUE"""),45616.0) -> 45616 | Z30: =IFERROR(__xludf.DUMMYFUNCTION("""COMPUTED_VALUE"""),"D34-1R") -> D34-1R | AA30: =IFERROR(__xludf.DUMMYFUNCTION("""COMPUTED_VALUE"""),1.0) -> 1 | AB30: =IFERROR(__xludf.DUMMYFUNCTION("""COMPUTED_VALUE"""),77.0) -> 77 | AC30: =IFERROR(__xludf.DUMMYFUNCTION("""COMPUTED_VALUE"""),39.0) -> 39 | AD30: =IFERROR(__xludf.DUMMYFUNCTION("""COMPUTED_VALUE"""),39.0) -> 39
A31: =IFERROR(__xludf.DUMMYFUNCTION("""COMPUTED_VALUE"""),"Y") -> Y | B31: =IFERROR(__xludf.DUMMYFUNCTION("""COMPUTED_VALUE"""),"2") -> 2 | C31: =IFERROR(__xludf.DUMMYFUNCTION("""COMPUTED_VALUE"""),"253-258") -> 253-258 | D31: =IFERROR(__xludf.DUMMYFUNCTION("""COMPUTED_VALUE"""),45588.0) -> 45588 | E31: =IFERROR(__xludf.DUMMYFUNCTION("""COMPUTED_VALUE"""),45595.0) -> 45595 | F31: =IFERROR(__xludf.DUMMYFUNCTION("""COMPUTED_VALUE"""),45616.0) -> 45616 | G31: =IFERROR(__xludf.DUMMYFUNCTION("""COMPUTED_VALUE"""),"D34-1R") -> D34-1R | H31: =IFERROR(__xludf.DUMMYFUNCTION("""COMPUTED_VALUE"""),1.0) -> 1 | I31: =IFERROR(__xludf.DUMMYFUNCTION("""COMPUTED_VALUE"""),77.0) -> 77 | J31: =IFERROR(__xludf.DUMMYFUNCTION("""COMPUTED_VALUE"""),39.0) -> 39 | K31: =IFERROR(__xludf.DUMMYFUNCTION("""COMPUTED_VALUE"""),39.0) -> 39 | T31: =IFERROR(__xludf.DUMMYFUNCTION("""COMPUTED_VALUE"""),"Y") -> Y | U31: =IFERROR(__xludf.DUMMYFUNCTION("""COMPUTED_VALUE"""),"2") -> 2 | V31: =IFERROR(__xludf.DUMMYFUNCTION("""COMPUTED_VALUE"""),"265-270") -> 265-270 | W31: =IFERROR(__xludf.DUMMYFUNCTION("""COMPUTED_VALUE"""),45589.0) -> 45589 | X31: =IFERROR(__xludf.DUMMYFUNCTION("""COMPUTED_VALUE"""),45596.0) -> 45596 | Y31: =IFERROR(__xludf.DUMMYFUNCTION("""COMPUTED_VALUE"""),45617.0) -> 45617 | Z31: =IFERROR(__xludf.DUMMYFUNCTION("""COMPUTED_VALUE"""),"D34-1R") -> D34-1R | AA31: =IFERROR(__xludf.DUMMYFUNCTION("""COMPUTED_VALUE"""),79.0) -> 79 | AB31: =IFERROR(__xludf.DUMMYFUNCTION("""COMPUTED_VALUE"""),159.0) -> 159 | AC31: =IFERROR(__xludf.DUMMYFUNCTION("""COMPUTED_VALUE"""),41.0) -> 41 | AD31: =IFERROR(__xludf.DUMMYFUNCTION("""COMPUTED_VALUE"""),41.0) -> 41
